Workbook

Sheet Final Att.
B2: S.N. | C2: EMP CODE | D2: EMP NAME | E2: EMP FATHER'S NAME | F2: 1 | G2: 2 | H2: 3 | I2: 4 | J2: 5 | K2: 6 | L2: 7 | M2: 8 | N2: 9 | O2: 10 | P2: 11 | Q2: 12 | R2: 13 | S2: 14 | T2: 15 | U2: 16 | V2: 17 | W2: 18 | X2: 19 | Y2: 20 | Z2: 21 | AA2: 22 | AB2: 23 | AC2: 24 | AD2: 25 | AE2: 26 | AF2: 27 | AG2: 28 | AH2: 29 | AI2: 30 | AJ2: TOTAL | AK2: Total Days | AL2: Total Salary
B3: 1 | C3: 33496 | D3: PIPAL SINGH | E3: PRATAP SINGH | F3: P | G3: P | H3: P | J3: P | K3: P | L3: P | M3: P | N3: P | O3: P | Q3: P | R3: P | S3: P | T3: P | Z3: P | AA3: P | AB3: P | AC3: P | AE3: P | AF3: P | AH3: P | AI3: P | AJ3: =COUNTIF(F3:AI3,"p")+COUNTIF(F3:AI3,"pp")+COUNTIF(F3:AI3,"pp") -> 21 | AK3: 21 | AL3: 11550
B4: 2 | C4: 33497 | D4: JASBIR SINGH | E4: KASHMIR SINGH | Q4: P | R4: P | S4: P | T4: P | V4: P | W4: P | X4: P | Y4: P | Z4: P | AA4: P | AB4: P | AC4: P | AE4: P | AF4: P | AG4: P | AH4: P | AJ4: =COUNTIF(F4:AI4,"p")+COUNTIF(F4:AI4,"pp")+COUNTIF(F4:AI4,"pp") -> 16 | AK4: 16 | AL4: 8800
B5: 3 | C5: 33498 | D5: SHAKTI KUMAR | E5: MURGESH | F5: P | G5: P | H5: P | I5: P | K5: P | L5: PP | M5: P | N5: P | O5: P | P5: P | R5: P | S5: P | T5: PP | U5: P | V5: P | W5: P | Y5: P | Z5: P | AA5: P | AB5: P | AC5: P | AD5: P | AF5: P | AG5: P | AH5: P | AI5: P | AJ5: =COUNTIF(F5:AI5,"p")+COUNTIF(F5:AI5,"pp")+COUNTIF(F5:AI5,"pp") -> 28 | AK5: 28 | AL5: 15400
B6: 4 | C6: 33499 | D6: HARJINDER SINGH | E6: KULWANT SINGH | F6: P | G6: P | H6: P | I6: P | L6: P | M6: P | N6: P | O6: P | P6: P | R6: P | S6: P | T6: P | U6: P | V6: P | W6: P | Y6: P | Z6: PP | AA6: P | AB6: P | AC6: P | AD6: P | AF6: P | AG6: P | AH6: P | AI6: P | AJ6: =COUNTIF(F6:AI6,"p")+COUNTIF(F6:AI6,"pp")+COUNTIF(F6:AI6,"pp") -> 26 | AK6: 26 | AL6: 14300
B7: 5 | C7: 33500 | D7: SANT SINGH | E7: VEER SINGH | F7: P | G7: P | H7: P | I7: P | K7: P | L7: P | M7: P | N7: P | O7: PP | P7: P | R7: P | S7: P | T7: P | U7: P | V7: P | Y7: P | Z7: P | AA7: P | AB7: PP | AC7: P | AD7: P | AF7: P | AG7: P | AH7: PP | AI7: P | AJ7: =COUNTIF(F7:AI7,"p")+COUNTIF(F7:AI7,"pp")+COUNTIF(F7:AI7,"pp") -> 28 | AK7: 28 | AL7: 15400
B8: 6 | C8: 33502 | D8: SOURAV | E8: PAWAN KUMAR | F8: P | G8: P | H8: PP | I8: P | K8: P | L8: P | M8: P | N8: P | O8: P | P8: P | R8: P | S8: P | T8: P | U8: P | V8: P | W8: P | Y8: P | Z8: P | AA8: P | AB8: P | AC8: P | AD8: P | AF8: P | AG8: P | AH8: P | AI8: P | AJ8: =COUNTIF(F8:AI8,"p")+COUNTIF(F8:AI8,"pp")+COUNTIF(F8:AI8,"pp") -> 27 | AK8: 27 | AL8: 15800
B9: 7 | C9: 33504 | D9: RAHUL KUMAR | E9: AJAY KUMAR | F9: P | K9: P | L9: P | M9: P | N9: P | AE9: P | AF9: P | AG9: P | AH9: P | AI9: P | AJ9: =COUNTIF(F9:AI9,"p")+COUNTIF(F9:AI9,"pp")+COUNTIF(F9:AI9,"pp") -> 10 | AK9: 10 | AL9: 5500
B10: 8 | C10: 33505 | D10: SANDEEP SINGH | E10: SUKHBIR SINGH | R10: P | S10: P | T10: P | U10: P | AH10: P | AI10: P | AJ10: =COUNTIF(F10:AI10,"p")+COUNTIF(F10:AI10,"pp")+COUNTIF(F10:AI10,"pp") -> 6 | AK10: 6 | AL10: 3600
B11: 9 | C11: 33506 | D11: DALBIR SINGH | E11: AJIT SINGH | F11: P | G11: P | H11: P | I11: P | J11: P | K11: P | L11: P | M11: P | N11: P | O11: P | P11: P | T11: P | U11: P | V11: P | W11: P | X11: P | AA11: P | AB11: P | AC11: P | AD11: P | AE11: P | AF11: P | AH11: P | AI11: P | AJ11: =COUNTIF(F11:AI11,"p")+COUNTIF(F11:AI11,"pp")+COUNTIF(F11:AI11,"pp") -> 24 | AK11: 24 | AL11: 13200
B12: 10 | C12: 33507 | D12: KARAN KUMAR | E12: INDERJIT | F12: P | G12: P | K12: P | L12: P | AJ12: =COUNTIF(F12:AI12,"p")+COUNTIF(F12:AI12,"pp")+COUNTIF(F12:AI12,"pp") -> 4 | AK12: 4 | AL12: 2400
B13: 11 | C13: 33509 | D13: NEETA | E13: SUDESH KUMAR | F13: P | G13: P | I13: P | J13: P | K13: P | L13: P | Q13: P | R13: P | S13: P | T13: P | W13: P | X13: P | Y13: P | Z13: P | AC13: P | AD13: P | AE13: P | AF13: P | AJ13: =COUNTIF(F13:AI13,"p")+COUNTIF(F13:AI13,"pp")+COUNTIF(F13:AI13,"pp") -> 18 | AK13: 18 | AL13: 9900
B14: 12 | C14: 33510 | D14: RAJIV KUMAR | E14: ROOP LAL | F14: P | G14: P | H14: P | K14: P | L14: P | M14: P | N14: P | O14: P | Q14: P | R14: P | S14: P | U14: P | V14: P | X14: P | Y14: P | Z14: P | AB14: P | AF14: P | AG14: P | AH14: P | AI14: P | AJ14: =COUNTIF(F14:AI14,"p")+COUNTIF(F14:AI14,"pp")+COUNTIF(F14:AI14,"pp") -> 21 | AK14: 21 | AL14: 11550
B15: 13 | C15: 33511 | D15: PRABHJOT SINGH | E15: TARSEM SINGH | G15: P | H15: P | J15: P | L15: P | U15: P | V15: P | X15: P | Y15: P | AC15: P | AE15: P | AF15: P | AG15: P | AH15: P | AI15: P | AJ15: =COUNTIF(F15:AI15,"p")+COUNTIF(F15:AI15,"pp")+COUNTIF(F15:AI15,"pp") -> 14 | AK15: 14 | AL15: =6600+1100 -> 7700
B16: 14 | C16: 33514 | D16: PREM PRAKASH | E16: DAVINDER | F16: P | G16: P | H16: P | I16: P | K16: P | L16: P | M16: P | N16: P | O16: P | P16: P | Q16: P | S16: P | T16: P | AI16: PP | AJ16: =COUNTIF(F16:AI16,"p")+COUNTIF(F16:AI16,"pp")+COUNTIF(F16:AI16,"pp") -> 15 | AK16: 15 | AL16: 8750
B17: 15 | C17: 33515 | D17: GURMAIL SINGH | E17: HARJINDER SINGH | F17: P | G17: P | H17: P | I17: P | J17: P | K17: P | L17: P | M17: P | N17: P | O17: P | P17: P | Q17: P | R17: P | S17: P | T17: P | U17: P | V17: P | W17: P | X17: P | Y17: P | Z17: P | AA17: P | AB17: P | AC17: P | AD17: P | AE17: P | AF17: P | AG17: P | AH17: P | AI17: P | AJ17: =COUNTIF(F17:AI17,"p")+COUNTIF(F17:AI17,"pp")+COUNTIF(F17:AI17,"pp") -> 30 | AK17: 30 | AL17: 16500
B18: 16 | C18: 33516 | D18: SARWAN SINGH | E18: HARBHAJAN SINGH | F18: P | H18: P | I18: P | J18: P | L18: P | M18: P | N18: P | R18: P | S18: P | T18: P | AJ18: =COUNTIF(F18:AI18,"p")+COUNTIF(F18:AI18,"pp")+COUNTIF(F18:AI18,"pp") -> 10 | AK18: 10 | AL18: 7500
B19: 17 | C19: 33517 | D19: SUKHWINDER SINGH | E19: JASWANT SINGH | F19: P | U19: P | V19: P | W19: P | X19: P | Y19: P | Z19: P | AA19: P | AB19: P | AC19: P | AD19: P | AE19: P | AF19: P | AG19: P | AH19: P | AI19: P | AJ19: =COUNTIF(F19:AI19,"p")+COUNTIF(F19:AI19,"pp")+COUNTIF(F19:AI19,"pp") -> 16 | AK19: 16 | AL19: 8800
B20: 18 | C20: 33518 | D20: VINOD KUMAR | E20: JASPAL | F20: P | G20: P | H20: P | I20: P | J20: P | M20: P | N20: P | O20: P | P20: P | Q20: P | T20: P | U20: P | V20: P | W20: P | X20: P | AA20: P | AB20: P | AC20: P | AD20: P | AE20: P | AF20: P | AH20: P | AI20: P | AJ20: =COUNTIF(F20:AI20,"p")+COUNTIF(F20:AI20,"pp")+COUNTIF(F20:AI20,"pp") -> 23 | AK20: 23 | AL20: 13800
B21: 19 | C21: 33522 | D21: SUNIL KUMAR | E21: MISHRI LAL | F21: P | G21: P | H21: P | I21: P | L21: P | M21: P | N21: P | O21: P | P21: P | R21: P | S21: P | T21: P | U21: P | V21: P | W21: P | Y21: PP | Z21: P | AA21: P | AB21: P | AC21: P | AD21: P | AF21: P | AG21: P | AH21: P | AI21: P | AJ21: =COUNTIF(F21:AI21,"p")+COUNTIF(F21:AI21,"pp")+COUNTIF(F21:AI21,"pp") -> 26 | AK21: 26 | AL21: 14300
B22: 20 | C22: 33526 | D22: ASHWANI SINGH | E22: MANN SINGH | F22: P | G22: P | H22: P | I22: P | K22: P | L22: P | M22: P | N22: P | O22: P | P22: P | R22: P | S22: P | T22: P | U22: P | V22: P | W22: P | Y22: P | Z22: P | AA22: P | AB22: P | AC22: P | AD22: P | AF22: P | AG22: P | AH22: P | AI22: P | AJ22: =COUNTIF(F22:AI22,"p")+COUNTIF(F22:AI22,"pp")+COUNTIF(F22:AI22,"pp") -> 26 | AK22: 26 | AL22: 15600
B23: 21 | C23: 33530 | D23: DAVINDER SINGH | E23: LAKHWINDER SINGH | K23: P | L23: P | M23: P | O23: P | P23: P | Q23: P | R23: P | V23: P | W23: P | X23: P | Z23: P | AA23: P | AB23: P | AF23: P | AG23: P | AH23: P | AJ23: =COUNTIF(F23:AI23,"p")+COUNTIF(F23:AI23,"pp")+COUNTIF(F23:AI23,"pp") -> 16 | AK23: 16 | AL23: 11200
B24: 22 | C24: 33532 | D24: SURINDER KUMAR | E24: KARAM CHAND | H24: P | I24: P | J24: P | T24: P | U24: P | Z24: P | AA24: P | AJ24: =COUNTIF(F24:AI24,"p")+COUNTIF(F24:AI24,"pp")+COUNTIF(F24:AI24,"pp") -> 7 | AK24: 7 | AL24: 4450
B25: 23 | C25: 33533 | D25: RAJBIR SINGH | E25: TASVIR SINGH | F25: P | G25: P | S25: P | T25: P | U25: P | V25: P | W25: P | X25: P | Y25: P | Z25: P | AJ25: =COUNTIF(F25:AI25,"p")+COUNTIF(F25:AI25,"pp")+COUNTIF(F25:AI25,"pp") -> 10 | AK25: 10 | AL25: 5500
B26: 24 | C26: 33534 | D26: SUGREEV | E26: MAHAVEER | F26: P | G26: PP | H26: P | I26: P | K26: P | L26: P | M26: P | N26: PP | O26: P | P26: P | R26: P | S26: P | T26: P | U26: P | V26: P | W26: P | Y26: P | Z26: P | AA26: P | AB26: P | AC26: P | AD26: P | AF26: P | AG26: P | AH26: P | AI26: P | AJ26: =COUNTIF(F26:AI26,"p")+COUNTIF(F26:AI26,"pp")+COUNTIF(F26:AI26,"pp") -> 28 | AK26: 28 | AL26: 15400
B27: 25 | C27: 33539 | D27: GURWINDER SINGH | E27: SATNAM SINGH | F27: P | G27: P | H27: P | I27: P | J27: P | M27: P | N27: P | O27: P | Q27: P | R27: P | S27: P | T27: P | U27: P | V27: P | AB27: P | AC27: P | AE27: P | AF27: P | AG27: P | AH27: P | AI27: P | AJ27: =COUNTIF(F27:AI27,"p")+COUNTIF(F27:AI27,"pp")+COUNTIF(F27:AI27,"pp") -> 21 | AK27: 21 | AL27: 11550
B28: 26 | C28: 33540 | D28: BALVIR CHAND | E28: KANSRAJ | F28: P | G28: P | H28: P | J28: P | K28: P | L28: P | M28: P | N28: P | O28: P | Q28: P | R28: P | S28: P | T28: P | X28: P | Y28: P | Z28: P | AA28: P | AB28: P | AC28: P | AE28: P | AF28: P | AG28: P | AH28: P | AI28: P | AJ28: =COUNTIF(F28:AI28,"p")+COUNTIF(F28:AI28,"pp")+COUNTIF(F28:AI28,"pp") -> 24 | AK28: 24 | AL28: 14400
B29: 27 | C29: 33547 | D29: SUKHWINDER SINGH | E29: PAL SINGH | G29: P | H29: P | I29: P | J29: P | K29: P | L29: P | M29: P | N29: P | O29: P | P29: P | Q29: P | R29: P | S29: P | T29: P | U29: P | V29: P | AB29: P | AC29: P | AD29: P | AE29: P | AF29: P | AG29: P | AH29: P | AI29: P | AJ29: =COUNTIF(F29:AI29,"p")+COUNTIF(F29:AI29,"pp")+COUNTIF(F29:AI29,"pp") -> 24 | AK29: 21 | AL29: 12600
B30: 28 | C30: 33549 | D30: CHARANJIT SINGH | E30: GURMUKH SINGH | H30: P | I30: P | J30: P | K30: P | AJ30: =COUNTIF(F30:AI30,"p")+COUNTIF(F30:AI30,"pp")+COUNTIF(F30:AI30,"pp") -> 4 | AK30: 4 | AL30: 2200
B31: 29 | C31: 33556 | D31: NARINDER SHARMA | E31: HIRA LAL | F31: P | G31: P | H31: P | I31: P | K31: P | L31: P | M31: P | N31: P | O31: P | P31: P | S31: P | T31: P | U31: P | V31: P | W31: P | Y31: P | Z31: P | AA31: P | AB31: P | AC31: P | AD31: P | AF31: P | AI31: P | AJ31: =COUNTIF(F31:AI31,"p")+COUNTIF(F31:AI31,"pp")+COUNTIF(F31:AI31,"pp") -> 23 | AK31: 23 | AL31: 12650
B32: 30 | C32: 33567 | D32: NARENDER | E32: CHANDER BHAN | F32: P | G32: P | H32: P | I32: P | J32: P | K32: P | L32: P | M32: P | N32: P | O32: P | P32: P | Q32: P | R32: P | S32: P | T32: P | U32: P | V32: P | W32: P | X32: P | Y32: P | Z32: P | AA32: P | AB32: P | AC32: P | AD32: P | AE32: P | AF32: P | AG32: P | AH32: P | AI32: P | AJ32: =COUNTIF(F32:AI32,"p")+COUNTIF(F32:AI32,"pp")+COUNTIF(F32:AI32,"pp") -> 30 | AK32: 33 | AL32: 18150
B33: 31 | C33: 33568 | D33: SAHIL BAWA | E33: RAMAN KUMAR | O33: P | P33: P | Q33: P | R33: P | AG33: P | AH33: P | AI33: P | AJ33: =COUNTIF(F33:AI33,"p")+COUNTIF(F33:AI33,"pp")+COUNTIF(F33:AI33,"pp") -> 7 | AK33: 7 | AL33: 3850
B34: 32 | C34: 33572 | D34: GURLAL SINGH | E34: HARPREET SINGH | G34: P | H34: P | K34: P | L34: P | M34: P | N34: P | U34: P | V34: P | W34: P | X34: P | AJ34: =COUNTIF(F34:AI34,"p")+COUNTIF(F34:AI34,"pp")+COUNTIF(F34:AI34,"pp") -> 10 | AK34: 10 | AL34: 5580
B35: 34 | C35: 33576 | D35: PRAVEEN KUMAR | E35: SANJAY KUMAR | F35: P | G35: P | H35: P | I35: P | J35: P | K35: P | L35: P | M35: P | N35: P | S35: P | T35: P | U35: P | V35: P | AH35: P | AI35: P | AJ35: =COUNTIF(F35:AI35,"p")+COUNTIF(F35:AI35,"pp")+COUNTIF(F35:AI35,"pp") -> 15 | AK35: 15 | AL35: 8350
B36: 35 | C36: 33577 | D36: BALWINDER KUMAR | E36: BABU RAM | F36: P | G36: P | I36: P | J36: P | K36: P | L36: P | P36: P | Q36: P | R36: P | S36: P | W36: P | X36: P | Y36: P | Z36: P | AD36: P | AE36: P | AF36: P | AG36: P | AJ36: =COUNTIF(F36:AI36,"p")+COUNTIF(F36:AI36,"pp")+COUNTIF(F36:AI36,"pp") -> 18 | AK36: 18 | AL36: 10800
B37: 36 | C37: 33578 | D37: ARPIT GUPTA | E37: ANIL GUPTA | F37: P | G37: P | H37: P | J37: P | K37: P | L37: P | M37: P | N37: P | O37: P | Q37: P | R37: P | S37: P | T37: P | W37: P | X37: P | Y37: P | Z37: P | AA37: P | AF37: P | AG37: P | AJ37: =COUNTIF(F37:AI37,"p")+COUNTIF(F37:AI37,"pp")+COUNTIF(F37:AI37,"pp") -> 20 | AK37: 20 | AL37: 11200
B38: 37 | C38: 33580 | D38: ALESH | E38: SHRI LAL | G38: P | H38: P | I38: P | J38: P | K38: P | L38: P | M38: P | N38: P | S38: P | T38: P | U38: P | V38: P | W38: P | X38: P | Z38: P | AA38: P | AB38: P | AC38: P | AG38: P | AH38: P | AJ38: =COUNTIF(F38:AI38,"p")+COUNTIF(F38:AI38,"pp")+COUNTIF(F38:AI38,"pp") -> 20 | AK38: 20 | AL38: 1100
B39: 38 | C39: 33581 | D39: PAVAN KUMAR SINGH | E39: BUBHASH CHANDRA SINGH | F39: P | G39: P | H39: P | I39: P | J39: P | K39: P | L39: P | M39: P | N39: P | O39: P | P39: P | Q39: P | R39: P | S39: P | T39: P | U39: P | V39: P | W39: P | X39: P | Y39: P | Z39: P | AA39: P | AB39: P | AC39: P | AD39: P | AE39: P | AF39: P | AG39: P | AH39: P | AI39: P | AJ39: =COUNTIF(F39:AI39,"p")+COUNTIF(F39:AI39,"pp")+COUNTIF(F39:AI39,"pp") -> 30 | AK39: 30 | AL39: 18000
B40: 39 | C40: 33585 | D40: ARSHDEEP SINGH | E40: CHARANJEET SINGH | K40: P | L40: P | M40: P | N40: P | O40: P | P40: P | Q40: P | R40: P | T40: P | U40: P | V40: P | W40: P | Y40: P | Z40: P | AA40: P | AB40: P | AH40: P | AI40: P | AJ40: =COUNTIF(F40:AI40,"p")+COUNTIF(F40:AI40,"pp")+COUNTIF(F40:AI40,"pp") -> 18 | AK40: 18 | AL40: 9900
B41: 40 | C41: 33586 | D41: SONU KASHYAP | E41: RAMDAS | H41: P | I41: P | J41: P | K41: P | L41: P | P41: P | Q41: P | R41: P | T41: P | U41: P | V41: P | W41: P | X41: P | Y41: P | Z41: P | AA41: P | AB41: P | AC41: P | AD41: P | AE41: P | AF41: P | AG41: P | AH41: P | AI41: P | AJ41: =COUNTIF(F41:AI41,"p")+COUNTIF(F41:AI41,"pp")+COUNTIF(F41:AI41,"pp") -> 24 | AK41: 24 | AL41: 13200
...

Sheet 12054-53
B2: Masure Project Pvt. Ltd. | AM2: Rate | AN2: Monthy Salary
B3: OBHS Attendance sheet of 12053-54 (Rake-01) Month:- Jun-2026 Site Name:- Amritsar OBHS (Attendance Day Per trip:- 01)
B4: S.N. | C4: EMP CODE | D4: TA ID No. | E4: EMP Name | F4: Father's Name | G4: Dig | H4: 1 | I4: 2 | J4: 3 | K4: 4 | L4: 5 | M4: 6 | N4: 7 | O4: 8 | P4: 9 | Q4: 10 | R4: 11 | S4: 12 | T4: 13 | U4: 14 | V4: 15 | W4: 16 | X4: 17 | Y4: 18 | Z4: 19 | AA4: 20 | AB4: 21 | AC4: 22 | AD4: 23 | AE4: 24 | AF4: 25 | AG4: 26 | AH4: 27 | AI4: 28 | AJ4: 29 | AK4: 30 | AL4: Total
B5: 1 | C5: 33540 | E5: BALVIR CHAND | F5: KANSRAJ | G5: EHK | H5: P | I5: P | J5: P | L5: P | M5: P | N5: P | O5: P | P5: P | Q5: P | S5: P | T5: P | U5: P | V5: P | Z5: P | AA5: P | AB5: P | AC5: P | AD5: P | AE5: P | AG5: P | AH5: P | AI5: P | AJ5: P | AK5: P | AL5: =COUNTIF(G5:AK5,"P")+COUNTIF(G5:AK5,"PP")+COUNTIF(G5:AK5,"PP") -> 24 | AM5: 600 | AN5: =AL5*AM5 -> 14400
B6: 2 | C6: 33872 | E6: MONEY KUMAR | F6: TARLOK RAJ | G6: OBHS | H6: P | I6: P | J6: P | L6: P | M6: P | N6: P | O6: P | P6: P | Q6: P | S6: P | T6: P | U6: P | V6: P | W6: P | X6: P | Z6: P | AA6: P | AB6: P | AC6: P | AD6: P | AE6: P | AH6: P | AI6: P | AJ6: P | AK6: P | AL6: =COUNTIF(G6:AK6,"P")+COUNTIF(G6:AK6,"PP")+COUNTIF(G6:AK6,"PP") -> 25 | AM6: 550 | AN6: =AL6*AM6 -> 13750
B7: 3 | C7: 33511 | E7: PRABHJOT SINGH | F7: TARSEM SINGH | G7: OBHS | L7: P | N7: P | AC7: P | AD7: P | AE7: P | AG7: P | AH7: P | AI7: P | AJ7: P | AK7: P | AL7: =COUNTIF(G7:AK7,"P")+COUNTIF(G7:AK7,"PP")+COUNTIF(G7:AK7,"PP") -> 10 | AM7: 550 | AN7: =AL7*AM7 -> 5500
B8: 4 | C8: 33496 | E8: PIPAL SINGH | F8: PRATAP SINGH | G8: OBHS | H8: P | I8: P | J8: P | L8: P | M8: P | N8: P | O8: P | P8: P | Q8: P | S8: P | T8: P | U8: P | V8: P | AB8: P | AC8: P | AD8: P | AE8: P | AG8: P | AH8: P | AJ8: P | AK8: P | AL8: =COUNTIF(G8:AK8,"P")+COUNTIF(G8:AK8,"PP")+COUNTIF(G8:AK8,"PP") -> 21 | AM8: 550 | AN8: =AL8*AM8 -> 11550
B9: 5 | C9: 33539 | E9: GURWINDER SINGH | F9: SATNAM SINGH | G9: OBHS | O9: P | P9: P | Q9: P | S9: P | T9: P | U9: P | V9: P | W9: P | X9: P | AD9: P | AE9: P | AG9: P | AH9: P | AI9: P | AJ9: P | AK9: P | AL9: =COUNTIF(G9:AK9,"P")+COUNTIF(G9:AK9,"PP")+COUNTIF(G9:AK9,"PP") -> 16 | AM9: 550 | AN9: =AL9*AM9 -> 8800
B10: 6 | C10: 33510 | E10: RAJIV KUMAR | F10: ROOP LAL | G10: OBHS | H10: P | I10: P | J10: P | M10: P | N10: P | O10: P | P10: P | Q10: P | S10: P | T10: P | U10: P | W10: P | X10: P | Z10: P | AA10: P | AB10: P | AD10: P | AH10: P | AI10: P | AJ10: P | AK10: P | AL10: =COUNTIF(G10:AK10,"P")+COUNTIF(G10:AK10,"PP")+COUNTIF(G10:AK10,"PP") -> 21 | AM10: 550 | AN10: =AL10*AM10 -> 11550
B11: 7 | C11: 33793 | E11: JAIMEET SINGH | F11: SANTOKH SINGH | G11: OBHS | J11: P | AL11: =COUNTIF(G11:AK11,"P")+COUNTIF(G11:AK11,"PP")+COUNTIF(G11:AK11,"PP") -> 1 | AM11: 550 | AN11: =AL11*AM11 -> 550
B12: 8 | C12: 33578 | E12: ARPIT GUPTA | F12: ANIL GUPTA | G12: OBHS | H12: P | I12: P | J12: P | L12: P | M12: P | N12: P | O12: P | P12: P | Q12: P | S12: P | T12: P | U12: P | V12: P | AA12: P | AL12: =COUNTIF(G12:AK12,"P")+COUNTIF(G12:AK12,"PP")+COUNTIF(G12:AK12,"PP") -> 14 | AM12: 550 | AN12: =AL12*AM12 -> 7700
B13: 9 | C13: 34167 | E13: SURENDER | F13: SHIV CHARAN | G13: OBHS | H13: P | I13: P | AL13: =COUNTIF(G13:AK13,"P")+COUNTIF(G13:AK13,"PP")+COUNTIF(G13:AK13,"PP") -> 2 | AM13: 550 | AN13: =AL13*AM13 -> 1100
B14: 10 | C14: 33661 | E14: DEEPAK | F14: AJIT SINGH | G14: OBHS | W14: P | Z14: P | AL14: =COUNTIF(G14:AK14,"P")+COUNTIF(G14:AK14,"PP")+COUNTIF(G14:AK14,"PP") -> 2 | AM14: 550 | AN14: =AL14*AM14 -> 1100
B15: 11 | C15: 33849 | E15: AJAY KUMAR | F15: RAM VILAS | G15: OBHS | M15: P | X15: P | AL15: =COUNTIF(G15:AK15,"P")+COUNTIF(G15:AK15,"PP")+COUNTIF(G15:AK15,"PP") -> 2 | AM15: 550 | AN15: =AL15*AM15 -> 1100
B16: 12 | C16: 33638 | E16: KAMALDEEP | F16: SUNIL KUMAR | G16: OBHS | Z16: P | AA16: P | AB16: P | AC16: P | AL16: =COUNTIF(G16:AK16,"P")+COUNTIF(G16:AK16,"PP")+COUNTIF(G16:AK16,"PP") -> 4 | AM16: 550 | AN16: =AL16*AM16 -> 2200
B17: 13 | C17: 34014 | E17: SUJAL PAL | F17: CHARAN PAL | G17: OBHS | L17: P | AL17: =COUNTIF(G17:AK17,"P")+COUNTIF(G17:AK17,"PP")+COUNTIF(G17:AK17,"PP") -> 1 | AM17: 550 | AN17: =AL17*AM17 -> 550
B18: 14 | C18: 34166 | E18: SIKANDER | F18: KALA RAM | G18: OBHS | W18: P | X18: P | AL18: =COUNTIF(G18:AK18,"P")+COUNTIF(G18:AK18,"PP")+COUNTIF(G18:AK18,"PP") -> 2 | AM18: 550 | AN18: =AL18*AM18 -> 1100
B19: 15 | C19: 34279 | E19: GURPREET SINGH | F19: AJIT SINGH | G19: OBHS | X19: P | AL19: =COUNTIF(G19:AK19,"P")+COUNTIF(G19:AK19,"PP")+COUNTIF(G19:AK19,"PP") -> 1 | AM19: 550 | AN19: =AL19*AM19 -> 550
B20: 16 | C20: 34686 | E20: SURAJ | F20: RAM MILAN | G20: OBHS | V20: P | AL20: =COUNTIF(G20:AK20,"P")+COUNTIF(G20:AK20,"PP")+COUNTIF(G20:AK20,"PP") -> 1 | AM20: 550 | AN20: =AL20*AM20 -> 550
B21: 17 | C21: 33720 | E21: ATUL SHARMA | F21: GIRISH SHARMA | G21: OBHS | Z21: P | AA21: P | AB21: P | AC21: P | AD21: P | AL21: =COUNTIF(G21:AK21,"P")+COUNTIF(G21:AK21,"PP")+COUNTIF(G21:AK21,"PP") -> 5 | AM21: 550 | AN21: =AL21*AM21 -> 2750
B22: 18 | C22: 34096 | E22: GURINDER SINGH | F22: SUKHWINDER SINGH | G22: OBHS | AC22: P | AL22: =COUNTIF(G22:AK22,"P")+COUNTIF(G22:AK22,"PP")+COUNTIF(G22:AK22,"PP") -> 1 | AM22: 550 | AN22: =AL22*AM22 -> 550
B23: 19 | C23: 33697 | E23: VISHAL SINGH | F23: RAVI SINGH | G23: OBHS | W23: P | AL23: =COUNTIF(G23:AK23,"P")+COUNTIF(G23:AK23,"PP")+COUNTIF(G23:AK23,"PP") -> 1 | AM23: 550 | AN23: =AL23*AM23 -> 550
B24: Total Per Day | H24: =COUNTIF(H5:H23,"P")+COUNTIF(H5:H23,"PP")+COUNTIF(H5:H23,"PP") -> 6 | I24: =COUNTIF(I5:I23,"P")+COUNTIF(I5:I23,"PP")+COUNTIF(I5:I23,"PP") -> 6 | J24: =COUNTIF(J5:J23,"P")+COUNTIF(J5:J23,"PP")+COUNTIF(J5:J23,"PP") -> 6 | K24: =COUNTIF(K5:K23,"P")+COUNTIF(K5:K23,"PP")+COUNTIF(K5:K23,"PP") -> 0 | L24: =COUNTIF(L5:L23,"P")+COUNTIF(L5:L23,"PP")+COUNTIF(L5:L23,"PP") -> 6 | M24: =COUNTIF(M5:M23,"P")+COUNTIF(M5:M23,"PP")+COUNTIF(M5:M23,"PP") -> 6 | N24: =COUNTIF(N5:N23,"P")+COUNTIF(N5:N23,"PP")+COUNTIF(N5:N23,"PP") -> 6 | O24: =COUNTIF(O5:O23,"P")+COUNTIF(O5:O23,"PP")+COUNTIF(O5:O23,"PP") -> 6 | ... AK24: =COUNTIF(AK5:AK23,"P")+COUNTIF(AK5:AK23,"PP")+COUNTIF(AK5:AK23,"PP") -> 6 | AL24: =SUM(AL5:AL23) -> 154 | AN24: =SUM(AN5:AN23) -> 85900

Sheet 12422-21
B2: Masure Project Pvt. Ltd. | AM2: Rate | AN2: Monthly Salary
B3: OBHS Attendance sheet of 12422/21 (Rake-01) Month:- JUNE-2026 Site Name:- Amritsar OBHS (Attendance Day Per trip:- 04)
B4: S.N. | C4: EMP CODE | D4: TA ID No. | E4: EMP Name | F4: Father's Name | G4: Dig | H4: 1 | I4: 2 | J4: 3 | K4: 4 | L4: 5 | M4: 6 | N4: 7 | O4: 8 | P4: 9 | Q4: 10 | R4: 11 | S4: 12 | T4: 13 | U4: 14 | V4: 15 | W4: 16 | X4: 17 | Y4: 18 | Z4: 19 | AA4: 20 | AB4: 21 | AC4: 22 | AD4: 23 | AE4: 24 | AF4: 25 | AG4: 26 | AH4: 27 | AI4: 28 | AJ4: 29 | AK4: 30 | AL4: Total
B5: 1 | C5: 33526 | E5: ASHWANI SINGH | F5: MANN SINGH | G5: EHK | H5: P | I5: P | J5: P | K5: P | O5: P | P5: P | Q5: P | R5: P | V5: P | W5: P | X5: P | Y5: P | AC5: P | AD5: P | AE5: P | AF5: P | AJ5: P | AK5: P | AL5: =COUNTIF(G5:AK5,"P")+COUNTIF(G5:AK5,"PP")+COUNTIF(G5:AK5,"PP") -> 18 | AM5: 600 | AN5: =AL5*AM5 -> 10800
B6: 2 | C6: 33791 | E6: RAVI | F6: SANTOKH SINGH | G6: OBHS | H6: P | I6: P | J6: P | K6: P | O6: P | P6: P | Q6: P | R6: P | AC6: P | AD6: P | AE6: P | AF6: P | AL6: =COUNTIF(G6:AK6,"P")+COUNTIF(G6:AK6,"PP")+COUNTIF(G6:AK6,"PP") -> 12 | AM6: 550 | AN6: =AL6*AM6 -> 6600
B7: 3 | C7: 34088 | E7: MANINDER SINGH | F7: RESHAM SINGH | G7: OBHS | H7: P | I7: P | J7: P | K7: P | O7: P | P7: P | Q7: P | R7: P | AL7: =COUNTIF(G7:AK7,"P")+COUNTIF(G7:AK7,"PP")+COUNTIF(G7:AK7,"PP") -> 8 | AM7: 550 | AN7: =AL7*AM7 -> 4400
B8: 4 | C8: 33887 | E8: MANPREET SINGH | F8: HARBANS SINGH | G8: OBHS | H8: P | I8: P | J8: P | K8: P | V8: P | W8: P | X8: P | Y8: P | AC8: P | AD8: P | AE8: P | AF8: P | AL8: =COUNTIF(G8:AK8,"P")+COUNTIF(G8:AK8,"PP")+COUNTIF(G8:AK8,"PP") -> 12 | AM8: 550 | AN8: =AL8*AM8 -> 6600
B9: 5 | C9: 33858 | E9: RAVINDER SINGH | F9: BALKAR SINGH | G9: OBHS | AJ9: P | AK9: P | AL9: =COUNTIF(G9:AK9,"P")+COUNTIF(G9:AK9,"PP")+COUNTIF(G9:AK9,"PP") -> 2 | AM9: 550 | AN9: =AL9*AM9 -> 1100
B10: 6 | C10: 33874 | E10: HARSHDEEP SINGH | F10: DALBIR SINGH | G10: OBHS | AJ10: P | AK10: P | AL10: =COUNTIF(G10:AK10,"P")+COUNTIF(G10:AK10,"PP")+COUNTIF(G10:AK10,"PP") -> 2 | AM10: 550 | AN10: =AL10*AM10 -> 1100
B11: 7 | C11: 34688 | E11: JASPINDER SINGH | F11: GURPREET SINGH | G11: OBHS | V11: P | W11: P | X11: P | Y11: P | AC11: P | AD11: P | AE11: P | AF11: P | AL11: =COUNTIF(G11:AK11,"P")+COUNTIF(G11:AK11,"PP")+COUNTIF(G11:AK11,"PP") -> 8 | AM11: 550 | AN11: =AL11*AM11 -> 4400
B12: 8 | C12: 34485 | E12: KARAN | F12: BINDER | G12: OBHS | V12: P | W12: P | X12: P | Y12: P | AL12: =COUNTIF(G12:AK12,"P")+COUNTIF(G12:AK12,"PP")+COUNTIF(G12:AK12,"PP") -> 4 | AM12: 550 | AN12: =AL12*AM12 -> 2200
B13: 9 | C13: 34484 | E13: AMANDEEP SINGH | F13: BALWINDER SINGH | G13: OBHS | V13: P | W13: P | X13: P | Y13: P | AJ13: P | AK13: P | AL13: =COUNTIF(G13:AK13,"P")+COUNTIF(G13:AK13,"PP")+COUNTIF(G13:AK13,"PP") -> 6 | AM13: 550 | AN13: =AL13*AM13 -> 3300
B14: 10 | C14: 34586 | E14: ARSHDEEP SINGH | F14: BALWINDER SINGH | G14: OBHS | AC14: P | AD14: P | AE14: P | AF14: P | AJ14: P | AK14: P | AL14: =COUNTIF(G14:AK14,"P")+COUNTIF(G14:AK14,"PP")+COUNTIF(G14:AK14,"PP") -> 6 | AM14: 550 | AN14: =AL14*AM14 -> 3300
B15: 11 | C15: 34285 | E15: PRINSPAL SINGH | F15: RAM SINGH | G15: OBHS | H15: P | I15: P | J15: P | K15: P | O15: P | P15: P | Q15: P | R15: P | AL15: =COUNTIF(G15:AK15,"P")+COUNTIF(G15:AK15,"PP")+COUNTIF(G15:AK15,"PP") -> 8 | AM15: 550 | AN15: =AL15*AM15 -> 4400
B16: 12 | C16: 34366 | E16: KARANDEEP SINGH | F16: HARJIT SINGH | G16: OBHS | O16: P | P16: P | Q16: P | R16: P | AL16: =COUNTIF(G16:AK16,"P")+COUNTIF(G16:AK16,"PP")+COUNTIF(G16:AK16,"PP") -> 4 | AM16: 550 | AN16: =AL16*AM16 -> 2200
B17: Total Per Day | H17: =COUNTIF(H5:H16,"P")+COUNTIF(H5:H16,"PP")+COUNTIF(H5:H16,"PP") -> 5 | I17: =COUNTIF(I5:I16,"P")+COUNTIF(I5:I16,"PP")+COUNTIF(I5:I16,"PP") -> 5 | J17: =COUNTIF(J5:J16,"P")+COUNTIF(J5:J16,"PP")+COUNTIF(J5:J16,"PP") -> 5 | K17: =COUNTIF(K5:K16,"P")+COUNTIF(K5:K16,"PP")+COUNTIF(K5:K16,"PP") -> 5 | L17: =COUNTIF(L5:L16,"P")+COUNTIF(L5:L16,"PP")+COUNTIF(L5:L16,"PP") -> 0 | M17: =COUNTIF(M5:M16,"P")+COUNTIF(M5:M16,"PP")+COUNTIF(M5:M16,"PP") -> 0 | N17: =COUNTIF(N5:N16,"P")+COUNTIF(N5:N16,"PP")+COUNTIF(N5:N16,"PP") -> 0 | O17: =COUNTIF(O5:O16,"P")+COUNTIF(O5:O16,"PP")+COUNTIF(O5:O16,"PP") -> 5 | ... AK17: =COUNTIF(AK5:AK16,"P")+COUNTIF(AK5:AK16,"PP")+COUNTIF(AK5:AK16,"PP") -> 5 | AL17: =SUM(AL5:AL16) -> 90 | AN17: =SUM(AN5:AN16) -> 50400

Sheet 14680-79
B2: Masure Project Pvt. Ltd. | AM2: Rate | AN2: Monthly Salary
B3: OBHS Attendance sheet of 14680/79 (Rake-01) Month:- Jun-2026 Site Name:- Amritsar OBHS (Attendance Day Per trip:- 02)
B4: S No. | C4: EMP CODE | D4: TA ID No. | E4: EMP Name | F4: Father's Name | G4: Dig | H4: 1 | I4: 2 | J4: 3 | K4: 4 | L4: 5 | M4: 6 | N4: 7 | O4: 8 | P4: 9 | Q4: 10 | R4: 11 | S4: 12 | T4: 13 | U4: 14 | V4: 15 | W4: 16 | X4: 17 | Y4: 18 | Z4: 19 | AA4: 20 | AB4: 21 | AC4: 22 | AD4: 23 | AE4: 24 | AF4: 25 | AG4: 26 | AH4: 27 | AI4: 28 | AJ4: 29 | AK4: 30 | AL4: Total
B5: 1 | C5: 34071 | E5: MANPREET SINGH | F5: MANJIT SINGH | G5: EHK | H5: P | I5: P | L5: P | M5: P | N5: P | O5: P | P5: P | X5: p | Y5: p | AA5: P | AB5: P | AC5: P | AD5: P | AH5: P | AI5: P | AJ5: P | AK5: P | AL5: =COUNTIF(G5:AK5,"P")+COUNTIF(G5:AK5,"PP")+COUNTIF(G5:AK5,"PP") -> 17 | AM5: 600 | AN5: =AL5*AM5 -> 10200
B6: 2 | C6: 33792 | E6: ANOOP KUMAR | F6: KISHAN CHAND | G6: EHK | AE6: P | AF6: P | AL6: =COUNTIF(G6:AK6,"P")+COUNTIF(G6:AK6,"PP")+COUNTIF(G6:AK6,"PP") -> 2 | AM6: 600 | AN6: =AL6*AM6 -> 1200
B7: 3 | C7: 33865 | E7: YOGESH KUMAR | F7: PRAM CHAND SINGH | G7: OBHS | AG7: P | AH7: P | AI7: P | AJ7: P | AK7: P | AL7: =COUNTIF(G7:AK7,"P")+COUNTIF(G7:AK7,"PP")+COUNTIF(G7:AK7,"PP") -> 5 | AM7: 600 | AN7: =AL7*AM7 -> 3000
B8: 4 | C8: 33680 | E8: RAJPAL SINGH | F8: MOOL CHAND | G8: OBHS | AJ8: P | AK8: P | AL8: =COUNTIF(G8:AK8,"P")+COUNTIF(G8:AK8,"PP")+COUNTIF(G8:AK8,"PP") -> 2 | AM8: 570 | AN8: =AL8*AM8 -> 1140
B9: 5 | C9: 33910 | E9: GULFAM | F9: MUNNE | G9: OBHS | N9: P | O9: P | P9: P | Q9: P | R9: P | S9: P | T9: P | U9: P | V9: P | W9: P | X9: P | Y9: P | AL9: =COUNTIF(G9:AK9,"P")+COUNTIF(G9:AK9,"PP")+COUNTIF(G9:AK9,"PP") -> 12 | AM9: 570 | AN9: =AL9*AM9 -> 6840
B10: 6 | C10: 33720 | E10: ATUL SHARMA | F10: GIRISH SHARMA | G10: OBHS | H10: P | I10: P | J10: P | K10: P | L10: P | M10: P | N10: P | S10: P | T10: P | U10: P | V10: P | W10: P | X10: P | AL10: =COUNTIF(G10:AK10,"P")+COUNTIF(G10:AK10,"PP")+COUNTIF(G10:AK10,"PP") -> 13 | AM10: 570 | AN10: =AL10*AM10 -> 7410
B11: 7 | C11: 34006 | E11: AVTAR SINGH | F11: DARBARA SINGH | G11: OBHS | H11: P | I11: P | J11: P | O11: P | P11: P | S11: P | T11: P | U11: P | V11: P | X11: p | Y11: p | AB11: P | AC11: P | AD11: P | AE11: P | AL11: =COUNTIF(G11:AK11,"P")+COUNTIF(G11:AK11,"PP")+COUNTIF(G11:AK11,"PP") -> 15 | AM11: 570 | AN11: =AL11*AM11 -> 8550
B12: 8 | C12: 33676 | E12: SONU BAGHEL | F12: PREM SINGH | G12: OBHS | AK12: P | AL12: =COUNTIF(G12:AK12,"P")+COUNTIF(G12:AK12,"PP")+COUNTIF(G12:AK12,"PP") -> 1 | AM12: 570 | AN12: =AL12*AM12 -> 570
B13: 9 | C13: 33662 | E13: MAHINDER KUMAR | F13: MUNI LAL | G13: OBHS | AK13: P | AL13: =COUNTIF(G13:AK13,"P")+COUNTIF(G13:AK13,"PP")+COUNTIF(G13:AK13,"PP") -> 1 | AM13: 570 | AN13: =AL13*AM13 -> 570
B14: 10 | C14: 33608 | E14: YOGESH KUMAR PAL | F14: MANOJ KUMAR PAL | G14: OBHS | H14: P | AL14: =COUNTIF(G14:AK14,"P")+COUNTIF(G14:AK14,"PP")+COUNTIF(G14:AK14,"PP") -> 1 | AM14: 570 | AN14: =AL14*AM14 -> 570
B15: 11 | C15: 33576 | E15: PRAVEEN KUMAR | F15: SANJAY KUMAR | G15: OBHS | H15: P | I15: P | J15: P | K15: P | L15: P | AL15: =COUNTIF(G15:AK15,"P")+COUNTIF(G15:AK15,"PP")+COUNTIF(G15:AK15,"PP") -> 5 | AM15: 570 | AN15: =AL15*AM15 -> 2850
B16: 12 | C16: 33816 | E16: JATINDER | F16: AJAY KUMAR | G16: OBHS | I16: P | J16: P | AL16: =COUNTIF(G16:AK16,"P")+COUNTIF(G16:AK16,"PP")+COUNTIF(G16:AK16,"PP") -> 2 | AM16: 570 | AN16: =AL16*AM16 -> 1140
B17: 13 | C17: 34280 | E17: AJAY SINGH | F17: DHEERA SINGH | G17: OBHS | I17: P | J17: P | AL17: =COUNTIF(G17:AK17,"P")+COUNTIF(G17:AK17,"PP")+COUNTIF(G17:AK17,"PP") -> 2 | AM17: 570 | AN17: =AL17*AM17 -> 1140
B18: 14 | C18: 34166 | E18: SIKANDER | F18: KALA RAM | G18: OBHS | J18: P | K18: P | AE18: P | AF18: P | AL18: =COUNTIF(G18:AK18,"P")+COUNTIF(G18:AK18,"PP")+COUNTIF(G18:AK18,"PP") -> 4 | AM18: 570 | AN18: =AL18*AM18 -> 2280
B19: 15 | C19: 33711 | E19: SURAJ | F19: RANBIR KUMAR | G19: OBHS | K19: P | L19: P | N19: P | O19: P | P19: P | Q19: P | R19: P | S19: P | AL19: =COUNTIF(G19:AK19,"P")+COUNTIF(G19:AK19,"PP")+COUNTIF(G19:AK19,"PP") -> 8 | AM19: 570 | AN19: =AL19*AM19 -> 4560
B20: 16 | C20: 33675 | E20: ANUBHAV SHARMA | F20: SHYAM SUNDER SHARMA | G20: OBHS | K20: P | L20: P | R20: P | S20: P | T20: P | U20: P | V20: P | W20: P | X20: P | Y20: P | AL20: =COUNTIF(G20:AK20,"P")+COUNTIF(G20:AK20,"PP")+COUNTIF(G20:AK20,"PP") -> 10 | AM20: 570 | AN20: =AL20*AM20 -> 5700
B21: 17 | C21: 34008 | E21: DHEERAJ MISHRA | F21: MANOJ MISHRA | G21: EHK | AF21: P | AG21: P | AL21: =COUNTIF(G21:AK21,"P")+COUNTIF(G21:AK21,"PP")+COUNTIF(G21:AK21,"PP") -> 2 | AM21: 600 | AN21: =AL21*AM21 -> 1200
B22: 18 | C22: 33987 | E22: ARUN | F22: SURESH | G22: OBHS | AG22: P | AH22: P | AL22: =COUNTIF(G22:AK22,"P")+COUNTIF(G22:AK22,"PP")+COUNTIF(G22:AK22,"PP") -> 2 | AM22: 570 | AN22: =AL22*AM22 -> 1140
B23: 19 | C23: 34002 | E23: CHANDAN SAGAR | F23: NET RAM | G23: OBHS | R23: P | S23: P | AL23: =COUNTIF(G23:AK23,"P")+COUNTIF(G23:AK23,"PP")+COUNTIF(G23:AK23,"PP") -> 2 | AM23: 570 | AN23: =AL23*AM23 -> 1140
B24: Total Per Day | H24: =COUNTIF(H5:H23,"P")+COUNTIF(H5:H23,"PP")+COUNTIF(H5:H23,"PP") -> 5 | I24: =COUNTIF(I5:I23,"P")+COUNTIF(I12:I23,"PP")+COUNTIF(I12:I23,"PP") -> 6 | J24: =COUNTIF(J5:J23,"P")+COUNTIF(J12:J23,"PP")+COUNTIF(J12:J23,"PP") -> 6 | K24: =COUNTIF(K5:K23,"P")+COUNTIF(K12:K23,"PP")+COUNTIF(K12:K23,"PP") -> 5 | L24: =COUNTIF(L5:L23,"P")+COUNTIF(L12:L23,"PP")+COUNTIF(L12:L23,"PP") -> 5 | M24: =COUNTIF(M5:M23,"P")+COUNTIF(M12:M23,"PP")+COUNTIF(M12:M23,"PP") -> 2 | N24: =COUNTIF(N5:N23,"P")+COUNTIF(N12:N23,"PP")+COUNTIF(N12:N23,"PP") -> 4 | O24: =COUNTIF(O5:O23,"P")+COUNTIF(O12:O23,"PP")+COUNTIF(O12:O23,"PP") -> 4 | P24: =COUNTIF(P5:P23,"P")+COUNTIF(P12:P23,"PP")+COUNTIF(P12:P23,"PP") -> 4 | ... AK24: =COUNTIF(AK5:AK23,"P")+COUNTIF(AK12:AK23,"PP")+COUNTIF(AK12:AK23,"PP") -> 5 | AL24: =SUM(AL5:AL23) -> 106 | AN24: =SUM(AN5:AN23) -> 61200
B26: Masure Project Pvt. Ltd. | AM26: Rate | AN26: Monthly Salary
B27: OBHS Attendance sheet of 14680/79 (Rake-02) Month:- Jun-2026 Site Name:- Amritsar OBHS (Attendance Day Per trip:- 02)
B28: S No. | C28: EMP CODE | D28: TA ID No. | E28: EMP Name | F28: Father's Name | G28: Dig | H28: 1 | I28: 2 | J28: 3 | K28: 4 | L28: 5 | M28: 6 | N28: 7 | O28: 8 | P28: 9 | Q28: 10 | R28: 11 | S28: 12 | T28: 13 | U28: 14 | V28: 15 | W28: 16 | X28: 17 | Y28: 18 | Z28: 19 | AA28: 20 | AB28: 21 | AC28: 22 | AD28: 23 | AE28: 24 | AF28: 25 | AG28: 26 | AH28: 27 | AI28: 28 | AJ28: 29 | AK28: 30 | AL28: Total
B29: 1 | C29: 33869 | E29: RAJ KUMAR | F29: JAGDISH LAL | G29: EHK | H29: P | AL29: =COUNTIF(G29:AK29,"P")+COUNTIF(G29:AK29,"PP")+COUNTIF(G29:AK29,"PP") -> 1 | AM29: 600 | AN29: =AL29*AM29 -> 600
B30: 2 | C30: 34058 | E30: SYED KHALID WALIED | F30: SYED ZAHID AHMAD | G30: EHK | J30: P | K30: P | L30: P | M30: P | N30: P | S30: P | T30: P | U30: P | V30: P | W30: P | X30: P | AB30: P | AC30: P | AD30: P | AE30: P | AL30: =COUNTIF(G30:AK30,"P")+COUNTIF(G30:AK30,"PP")+COUNTIF(G30:AK30,"PP") -> 15 | AM30: 600 | AN30: =AL30*AM30 -> 9000
B31: 3 | C31: 33572 | E31: GURLAL SINGH | F31: HARPREET SINGH | G31: OBHS | W31: P | X31: P | Z31: P | AA31: P | AL31: =COUNTIF(G31:AK31,"P")+COUNTIF(G31:AK31,"PP")+COUNTIF(G31:AK31,"PP") -> 4 | AM31: 570 | AN31: =AL31*AM31 -> 2280
B32: 1 | C32: 33578 | E32: ARPIT GUPTA | F32: ANIL GUPTA | G32: OBHS | X32: p | Y32: p | AB32: P | AC32: P | AH32: P | AI32: P | AL32: =COUNTIF(G32:AK32,"P")+COUNTIF(G32:AK32,"PP")+COUNTIF(G32:AK32,"PP") -> 6 | AM32: 570 | AN32: =AL32*AM32 -> 3420
B33: 2 | C33: 33638 | E33: KAMALDEEP | F33: SUNIL KUMAR | G33: OBHS | N33: P | O33: P | P33: P | Q33: P | S33: P | T33: P | U33: P | V33: P | X33: P | Y33: P | AL33: =COUNTIF(G33:AK33,"P")+COUNTIF(G33:AK33,"PP")+COUNTIF(G33:AK33,"PP") -> 10 | AM33: 570 | AN33: =AL33*AM33 -> 5700
B34: 3 | C34: 34185 | E34: UMESH KUMAR | F34: VEDPAL SINGH | G34: OBHS | O34: P | P34: P | AL34: =COUNTIF(G34:AK34,"P")+COUNTIF(G34:AK34,"PP")+COUNTIF(G34:AK34,"PP") -> 2 | AM34: 570 | AN34: =AL34*AM34 -> 1140
B35: 4 | C35: 34209 | E35: BHAGWANT SINGH | F35: JOGINDER LAL | G35: OBHS | H35: P | I35: P | AL35: =COUNTIF(G35:AK35,"P")+COUNTIF(G35:AK35,"PP")+COUNTIF(G35:AK35,"PP") -> 2 | AM35: 570 | AN35: =AL35*AM35 -> 1140
B36: 5 | C36: 33244 | E36: BHAGAT RAM | F36: HULASH RAM | G36: OBHS | T36: P | U36: P | AL36: =COUNTIF(G36:AK36,"P")+COUNTIF(G36:AK36,"PP")+COUNTIF(G36:AK36,"PP") -> 2 | AM36: 570 | AN36: =AL36*AM36 -> 1140
B37: 6 | C37: 33249 | E37: GANGADER TIWARI | F37: MADAN TIWARI | G37: OBHS | T37: P | U37: P | AL37: =COUNTIF(G37:AK37,"P")+COUNTIF(G37:AK37,"PP")+COUNTIF(G37:AK37,"PP") -> 2 | AM37: 570 | AN37: =AL37*AM37 -> 1140
B38: 7 | C38: 34651 | E38: GULSHAN | F38: BHAJAN SINGH | G38: OBHS | AG38: P | AH38: P | AL38: =COUNTIF(G38:AK38,"P")+COUNTIF(G38:AK38,"PP")+COUNTIF(G38:AK38,"PP") -> 2 | AM38: 570 | AN38: =AL38*AM38 -> 1140
B39: 8 | C39: 34644 | E39: AMRITPAL SINGH | F39: KULDEEP SINGH | G39: OBHS | AI39: P | AJ39: P | AL39: =COUNTIF(G39:AK39,"P")+COUNTIF(G39:AK39,"PP")+COUNTIF(G39:AK39,"PP") -> 2 | AM39: 570 | AN39: =AL39*AM39 -> 1140
B40: 9 | C40: 34286 | E40: VIKAS | F40: FIRTU RAM | G40: OBHS | V40: P | W40: P | AJ40: P | AK40: P | AL40: =COUNTIF(G40:AK40,"P")+COUNTIF(G40:AK40,"PP")+COUNTIF(G40:AK40,"PP") -> 4 | AM40: 570 | AN40: =AL40*AM40 -> 2280
B41: 10 | C41: 34584 | E41: SAHIL | F41: SHRI RAM | G41: OBHS | Z41: P | AA41: P | AD41: P | AE41: P | AG41: P | AH41: P | AL41: =COUNTIF(G41:AK41,"P")+COUNTIF(G41:AK41,"PP")+COUNTIF(G41:AK41,"PP") -> 6 | AM41: 570 | AN41: =AL41*AM41 -> 3420
B42: 11 | C42: 34586 | E42: ARSHDEEP SINGH | F42: BALWINDER SINGH | G42: OBHS | Z42: P | AA42: P | AL42: =COUNTIF(G42:AK42,"P")+COUNTIF(G42:AK42,"PP")+COUNTIF(G42:AK42,"PP") -> 2 | AM42: 570 | AN42: =AL42*AM42 -> 1140
...

Sheet 22488-87
B2: Masure Project Pvt. Ltd. | AM2: Rate | AN2: Monthly Salary
B3: OBHS Attendance sheet of 22488/87 (Rake-01) Month:- Jun-2026 Site Name:- Amritsar OBHS (Attendance Day Per trip:- 01)
B4: S No. | C4: EMP CODE | D4: TA ID No. | E4: EMP Name | F4: Father's Name | G4: Dig | H4: 1 | I4: 2 | J4: 3 | K4: 4 | L4: 5 | M4: 6 | N4: 7 | O4: 8 | P4: 9 | Q4: 10 | R4: 11 | S4: 12 | T4: 13 | U4: 14 | V4: 15 | W4: 16 | X4: 17 | Y4: 18 | Z4: 19 | AA4: 20 | AB4: 21 | AC4: 22 | AD4: 23 | AE4: 24 | AF4: 25 | AG4: 26 | AH4: 27 | AI4: 28 | AJ4: 29 | AK4: 30 | AL4: Total
B5: 1 | C5: 33514 | D5: 3 | E5: PREM PRAKASH | F5: DAVINDER | G5: EHK | H5: P | I5: P | J5: P | K5: P | M5: P | N5: P | U5: P | V5: P | AK5: PP | AL5: =COUNTIF(G5:AK5,"P")+COUNTIF(G5:AK5,"PP")+COUNTIF(G5:AK5,"PP") -> 10 | AM5: 600 | AN5: =AM5*AL5 -> 6000
B6: 2 | C6: 33502 | E6: SOURAV | F6: PAWAN KUMAR | G6: OBHS | H6: P | I6: P | J6: PP | K6: P | M6: P | N6: P | AK6: P | AL6: =COUNTIF(G6:AK6,"P")+COUNTIF(G6:AK6,"PP")+COUNTIF(G6:AK6,"PP") -> 8 | AM6: 550 | AN6: =AM6*AL6 -> 4400
C7: 33502 | E7: SOURAV | F7: PAWAN KUMAR | G7: EHK | O7: P | P7: P | Q7: P | R7: P | T7: P | U7: P | V7: P | W7: P | X7: P | Y7: p | AA7: P | AB7: P | AC7: P | AD7: P | AE7: P | AF7: P | AH7: P | AI7: P | AJ7: P | AL7: =COUNTIF(G7:AK7,"P")+COUNTIF(G7:AK7,"PP")+COUNTIF(G7:AK7,"PP") -> 19 | AM7: 600 | AN7: =AM7*AL7 -> 11400
B8: 3 | C8: 33556 | D8: 5 | E8: NARINDER SHARMA | F8: HIRA LAL | G8: OBHS | H8: P | I8: P | J8: P | K8: P | M8: P | N8: P | O8: P | P8: P | Q8: P | R8: P | U8: P | V8: P | W8: P | X8: P | Y8: p | AA8: P | AB8: P | AC8: P | AD8: P | AE8: P | AF8: P | AH8: P | AK8: P | AL8: =COUNTIF(G8:AK8,"P")+COUNTIF(G8:AK8,"PP")+COUNTIF(G8:AK8,"PP") -> 23 | AM8: 550 | AN8: =AM8*AL8 -> 12650
B9: 4 | C9: 33500 | D9: 16 | E9: SANT SINGH | F9: VEER SINGH | G9: OBHS | H9: P | I9: P | J9: P | K9: P | M9: P | N9: P | O9: P | P9: P | Q9: PP | R9: P | T9: P | U9: P | V9: P | W9: P | X9: P | AA9: P | AB9: P | AC9: P | AD9: PP | AE9: P | AF9: P | AH9: P | AI9: P | AJ9: PP | AK9: P | AL9: =COUNTIF(G9:AK9,"P")+COUNTIF(G9:AK9,"PP")+COUNTIF(G9:AK9,"PP") -> 28 | AM9: 550 | AN9: =AM9*AL9 -> 15400
B10: 5 | C10: 33522 | D10: 11 | E10: SUNIL KUMAR | F10: MISHRI LAL | G10: OBHS | H10: P | I10: P | J10: P | K10: P | N10: P | O10: P | P10: P | Q10: P | R10: P | T10: P | U10: P | V10: P | W10: P | X10: P | Y10: p | AA10: PP | AB10: P | AC10: P | AD10: P | AE10: P | AF10: P | AH10: P | AI10: P | AJ10: P | AK10: P | AL10: =COUNTIF(G10:AK10,"P")+COUNTIF(G10:AK10,"PP")+COUNTIF(G10:AK10,"PP") -> 26 | AM10: 550 | AN10: =AM10*AL10 -> 14300
B11: 6 | C11: 33498 | D11: 4 | E11: SHAKTI KUMAR | F11: MURGESH | G11: OBHS | H11: P | I11: P | J11: P | K11: P | M11: P | N11: PP | O11: P | P11: P | Q11: P | R11: P | T11: P | U11: P | V11: PP | W11: P | X11: P | Y11: p | AA11: P | AB11: P | AC11: P | AD11: P | AE11: P | AF11: P | AH11: P | AI11: P | AJ11: P | AK11: P | AL11: =COUNTIF(G11:AK11,"P")+COUNTIF(G11:AK11,"PP")+COUNTIF(G11:AK11,"PP") -> 28 | AM11: 550 | AN11: =AM11*AL11 -> 15400
B12: 7 | C12: 33534 | D12: 55 | E12: SUGREEV | F12: MAHAVEER | G12: OBHS | H12: P | I12: PP | J12: P | K12: P | M12: P | N12: P | O12: P | P12: PP | Q12: P | R12: P | T12: P | U12: P | V12: P | W12: P | X12: P | Y12: p | AA12: P | AB12: P | AC12: P | AD12: P | AE12: P | AF12: P | AH12: P | AI12: P | AJ12: P | AK12: P | AL12: =COUNTIF(G12:AK12,"P")+COUNTIF(G12:AK12,"PP")+COUNTIF(G12:AK12,"PP") -> 28 | AM12: 550 | AN12: =AM12*AL12 -> 15400
B13: 8 | C13: 33859 | D13: 25 | E13: SARABJEET SINGH | F13: AMRIK SINGH | G13: OBHS | H13: P | I13: P | J13: P | K13: P | M13: P | N13: P | P13: P | Q13: P | R13: P | T13: P | U13: P | V13: P | W13: PP | X13: P | Y13: p | AA13: P | AB13: P | AC13: P | AD13: P | AE13: P | AF13: P | AH13: P | AI13: P | AJ13: P | AK13: P | AL13: =COUNTIF(G13:AK13,"P")+COUNTIF(G13:AK13,"PP")+COUNTIF(G13:AK13,"PP") -> 26 | AM13: 550 | AN13: =AM13*AL13 -> 14300
B14: 9 | C14: 33499 | D14: 12 | E14: HARJINDER | F14: KULWANT SINGH | G14: OBHS | H14: P | I14: P | J14: P | K14: P | N14: P | O14: P | P14: P | Q14: P | R14: P | T14: P | U14: P | V14: P | W14: P | X14: P | Y14: p | AA14: P | AB14: PP | AC14: P | AD14: P | AE14: P | AF14: P | AH14: P | AI14: P | AJ14: P | AK14: P | AL14: =COUNTIF(G14:AK14,"P")+COUNTIF(G14:AK14,"PP")+COUNTIF(G14:AK14,"PP") -> 26 | AM14: 550 | AN14: =AM14*AL14 -> 14300
B15: 10 | C15: 34008 | E15: DHEERAJ MISHRA | F15: MANOJ MISHRA | G15: EHK | M15: P | AL15: =COUNTIF(G15:AK15,"P")+COUNTIF(G15:AK15,"PP")+COUNTIF(G15:AK15,"PP") -> 1 | AM15: 600 | AN15: =AM15*AL15 -> 600
B16: 11 | C16: 33662 | E16: MAHINDER KUMAR | F16: MUNI LAL | G16: OBHS | AI16: P | AJ16: P | AL16: =COUNTIF(G16:AK16,"P")+COUNTIF(G16:AK16,"PP")+COUNTIF(G16:AK16,"PP") -> 2 | AM16: 550 | AN16: =AM16*AL16 -> 1100
B17: 12 | C17: 33816 | E17: JATINDER | F17: AJAY KUMAR | G17: OBHS | Y17: p | AL17: =COUNTIF(G17:AK17,"P")+COUNTIF(G17:AK17,"PP")+COUNTIF(G17:AK17,"PP") -> 1 | AM17: 550 | AN17: =AM17*AL17 -> 550
B18: 13 | C18: 34686 | E18: SURAJ | F18: RAM MILAN | G18: OBHS | O18: P | P18: P | Q18: P | R18: P | T18: P | W18: P | X18: P | Y18: p | AA18: P | AC18: P | AD18: P | AE18: P | AF18: P | AH18: P | AJ18: P | AL18: =COUNTIF(G18:AK18,"P")+COUNTIF(G18:AK18,"PP")+COUNTIF(G18:AK18,"PP") -> 15 | AM18: 550 | AN18: =AM18*AL18 -> 8250
B19: Total Per Day | H19: =COUNTIF(H5:H18,"P")+COUNTIF(H5:H18,"PP")+COUNTIF(H5:H18,"PP") -> 9 | I19: =COUNTIF(I5:I18,"P")+COUNTIF(I5:I18,"PP")+COUNTIF(I5:I18,"PP") -> 10 | J19: =COUNTIF(J5:J18,"P")+COUNTIF(J5:J18,"PP")+COUNTIF(J5:J18,"PP") -> 10 | K19: =COUNTIF(K5:K18,"P")+COUNTIF(K5:K18,"PP")+COUNTIF(K5:K18,"PP") -> 9 | L19: =COUNTIF(L5:L18,"P")+COUNTIF(L5:L18,"PP")+COUNTIF(L5:L18,"PP") -> 0 | M19: =COUNTIF(M5:M18,"P")+COUNTIF(M5:M18,"PP")+COUNTIF(M5:M18,"PP") -> 8 | N19: =COUNTIF(N5:N18,"P")+COUNTIF(N5:N18,"PP")+COUNTIF(N5:N18,"PP") -> 10 | O19: =COUNTIF(O5:O18,"P")+COUNTIF(O5:O18,"PP")+COUNTIF(O5:O18,"PP") -> 8 | ... AK19: =COUNTIF(AK5:AK18,"P")+COUNTIF(AK5:AK18,"PP")+COUNTIF(AK5:AK18,"PP") -> 10 | AL19: =SUM(AL5:AL18) -> 241 | AN19: =SUM(AN5:AN18) -> 134050

Sheet 14650-49
B2: Masure Project Pvt. Ltd. | AM2: Rate | AN2: Monthly Salary
B3: OBHS Attendance sheet of 14650/49 (Rake-01) Month:- Jun-2026 Site Name:- Amritsar OBHS (Attendance Day Per trip:- 04)
B4: S.N. | C4: EMP CODE | D4: TA ID No. | E4: EMP Name | F4: Father's Name | G4: Dig | H4: 1 | I4: 2 | J4: 3 | K4: 4 | L4: 5 | M4: 6 | N4: 7 | O4: 8 | P4: 9 | Q4: 10 | R4: 11 | S4: 12 | T4: 13 | U4: 14 | V4: 15 | W4: 16 | X4: 17 | Y4: 18 | Z4: 19 | AA4: 20 | AB4: 21 | AC4: 22 | AD4: 23 | AE4: 24 | AF4: 25 | AG4: 26 | AH4: 27 | AI4: 28 | AJ4: 29 | AK4: 30 | AL4: Total
B5: 1 | C5: 33982 | D5: 135 | E5: SHIVA | F5: VIJENDRA SINGH | G5: EHK | V5: P | W5: P | X5: P | Y5: P | AL5: =COUNTIF(G5:AK5,"P")+COUNTIF(G5:AK5,"PP")+COUNTIF(G5:AK5,"PP") -> 4 | AM5: 600 | AN5: =AL5*AM5 -> 2400
B6: 2 | C6: 33547 | E6: SUKHWINDER SINGH | F6: PAL SINGH | G6: EHK | M6: P | N6: P | O6: P | P6: P | Q6: P | R6: P | S6: P | T6: P | AH6: P | AI6: P | AJ6: P | AK6: P | AL6: =COUNTIF(G6:AK6,"P")+COUNTIF(G6:AK6,"PP")+COUNTIF(G6:AK6,"PP") -> 12 | AM6: 600 | AN6: =AL6*AM6 -> 7200
B7: 3 | C7: 34585 | E7: LOVEDEEP SINGH | F7: SAWINDER SINGH | G7: EHK | AC7: P | AD7: P | AE7: P | AF7: P | AL7: =COUNTIF(G7:AK7,"P")+COUNTIF(G7:AK7,"PP")+COUNTIF(G7:AK7,"PP") -> 4 | AM7: 600 | AN7: =AL7*AM7 -> 2400
B8: 4 | C8: 33637 | E8: ARJUN | F8: PURAN | G8: OBHS | J8: P | K8: P | L8: P | M8: P | V8: P | W8: P | X8: P | Y8: P | AH8: P | AI8: P | AJ8: P | AK8: P | AL8: =COUNTIF(G8:AK8,"P")+COUNTIF(G8:AK8,"PP")+COUNTIF(G8:AK8,"PP") -> 12 | AM8: 550 | AN8: =AL8*AM8 -> 6600
B9: 5 | C9: 33517 | E9: SUKHWINDER SINGH | F9: JASWANT SINGH | G9: OBHS | AH9: P | AI9: P | AJ9: P | AK9: P | AL9: =COUNTIF(G9:AK9,"P")+COUNTIF(G9:AK9,"PP")+COUNTIF(G9:AK9,"PP") -> 4 | AM9: 550 | AN9: =AL9*AM9 -> 2200
B10: 6 | C10: 33654 | E10: AKASHDEEP SINGH | F10: SATNAM SINGH | G10: OBHS | M10: P | N10: P | O10: P | P10: P | AL10: =COUNTIF(G10:AK10,"P")+COUNTIF(G10:AK10,"PP")+COUNTIF(G10:AK10,"PP") -> 4 | AM10: 550 | AN10: =AL10*AM10 -> 2200
B11: 7 | C11: 33783 | E11: VISHAL | F11: SATNAM SINGH | G11: OBHS | M11: P | N11: P | O11: P | P11: P | AL11: =COUNTIF(G11:AK11,"P")+COUNTIF(G11:AK11,"PP")+COUNTIF(G11:AK11,"PP") -> 4 | AM11: 550 | AN11: =AL11*AM11 -> 2200
B12: 8 | C12: 33515 | D12: 45 | E12: GURMAIL SINGH | F12: HARJINDER SINGH | G12: OBHS | T12: P | U12: P | V12: P | W12: P | X12: P | Y12: P | Z12: P | AA12: P | AL12: =COUNTIF(G12:AK12,"P")+COUNTIF(G12:AK12,"PP")+COUNTIF(G12:AK12,"PP") -> 8 | AM12: 550 | AN12: =AL12*AM12 -> 4400
B13: 9 | C13: 33585 | E13: ARSHDEEP SINGH | F13: CHARANJEET SINGH | G13: OBHS | M13: P | N13: P | O13: P | P13: P | Q13: P | R13: P | S13: P | T13: P | V13: P | W13: P | X13: P | Y13: P | AA13: P | AB13: P | AC13: P | AD13: P | AL13: =COUNTIF(G13:AK13,"P")+COUNTIF(G13:AK13,"PP")+COUNTIF(G13:AK13,"PP") -> 16 | AM13: 550 | AN13: =AL13*AM13 -> 8800
B14: 10 | C14: 33857 | E14: DAVINDER SINGH | F14: RAM SINGH | G14: OBHS | T14: P | U14: P | V14: P | W14: P | X14: P | Y14: P | Z14: P | AA14: P | AL14: =COUNTIF(G14:AK14,"P")+COUNTIF(G14:AK14,"PP")+COUNTIF(G14:AK14,"PP") -> 8 | AM14: 550 | AN14: =AL14*AM14 -> 4400
B15: 11 | C15: 33794 | E15: VISHAL SINGH | F15: RAKESH SINGH | G15: OBHS | W15: P | X15: P | Y15: P | Z15: P | AA15: P | AB15: P | AC15: P | AD15: P | AE15: P | AF15: P | AG15: P | AH15: P | AL15: =COUNTIF(G15:AK15,"P")+COUNTIF(G15:AK15,"PP")+COUNTIF(G15:AK15,"PP") -> 12 | AM15: 550 | AN15: =AL15*AM15 -> 6600
B16: 12 | C16: 34469 | E16: AJAY SHARMA | F16: ASHWANI SHARMA | G16: OBHS | W16: P | X16: P | Y16: P | Z16: P | AA16: P | AB16: P | AC16: P | AD16: P | AE16: P | AF16: P | AG16: P | AH16: P | AL16: =COUNTIF(G16:AK16,"P")+COUNTIF(G16:AK16,"PP")+COUNTIF(G16:AK16,"PP") -> 12 | AM16: 550 | AN16: =AL16*AM16 -> 6600
B17: 13 | C17: 33849 | E17: AJAY KUMAR | F17: RAM VILAS | G17: OBHS | AC17: P | AD17: P | AE17: P | AF17: P | AL17: =COUNTIF(G17:AK17,"P")+COUNTIF(G17:AK17,"PP")+COUNTIF(G17:AK17,"PP") -> 4 | AM17: 550 | AN17: =AL17*AM17 -> 2200
B18: 14 | C18: 34583 | E18: RAKESH YADAV | F18: DEVI PARSHAD YADAV | G18: OBHS | AC18: P | AD18: P | AE18: P | AF18: P | AL18: =COUNTIF(G18:AK18,"P")+COUNTIF(G18:AK18,"PP")+COUNTIF(G18:AK18,"PP") -> 4 | AM18: 550 | AN18: =AL18*AM18 -> 2200
B19: 15 | C19: 34685 | E19: PRITPAL SINGH | F19: JASBIR SINGH | G19: OBHS | AC19: P | AD19: P | AE19: P | AF19: P | AL19: =COUNTIF(G19:AK19,"P")+COUNTIF(G19:AK19,"PP")+COUNTIF(G19:AK19,"PP") -> 4 | AM19: 550 | AN19: =AL19*AM19 -> 2200
B20: 16 | C20: 34002 | E20: CHANDAN SAGAR | F20: NET RAM | G20: OBHS | J20: P | K20: P | L20: P | M20: P | AL20: =COUNTIF(G20:AK20,"P")+COUNTIF(G20:AK20,"PP")+COUNTIF(G20:AK20,"PP") -> 4 | AM20: 550 | AN20: =AL20*AM20 -> 2200
B21: 17 | C21: 34279 | E21: GURPREET SINGH | F21: AJIT SINGH | G21: OBHS | O21: P | P21: P | Q21: P | R21: P | AL21: =COUNTIF(G21:AK21,"P")+COUNTIF(G21:AK21,"PP")+COUNTIF(G21:AK21,"PP") -> 4 | AM21: 550 | AN21: =AL21*AM21 -> 2200
B22: 18 | C22: 34093 | D22: 143 | E22: DEVENDRA AGRWAL | F22: VIRENDRA AGRAWAL | G22: OBHS | T22: P | U22: P | V22: P | W22: P | AL22: =COUNTIF(G22:AK22,"P")+COUNTIF(G22:AK22,"PP")+COUNTIF(G22:AK22,"PP") -> 4 | AM22: 550 | AN22: =AL22*AM22 -> 2200
B23: 19 | C23: 33509 | E23: NEETA | F23: SUDESH KUMAR | G23: OBHS | AE23: P | AF23: P | AG23: P | AH23: P | AL23: =COUNTIF(G23:AK23,"P")+COUNTIF(G23:AK23,"PP")+COUNTIF(G23:AK23,"PP") -> 4 | AM23: 550 | AN23: =AL23*AM23 -> 2200
B24: 20 | C24: 33694 | E24: VICKY | F24: PAPPU | G24: OBHS | M24: P | N24: P | O24: P | P24: P | T24: P | U24: P | V24: P | W24: P | AL24: =COUNTIF(G24:AK24,"P")+COUNTIF(G24:AK24,"PP")+COUNTIF(G24:AK24,"PP") -> 8 | AM24: 550 | AN24: =AL24*AM24 -> 4400
B25: 21 | C25: 34184 | E25: RAHUL KUMAR | F25: DEEPAK KUMAR | G25: OBHS | V25: P | W25: P | X25: P | Y25: P | AL25: =COUNTIF(G25:AK25,"P")+COUNTIF(G25:AK25,"PP")+COUNTIF(G25:AK25,"PP") -> 4 | AM25: 550 | AN25: =AL25*AM25 -> 2200
B26: 22 | C26: 33682 | E26: GAGANDEEP SINGH | F26: MANMOHAN SINGH | G26: OBHS | H26: P | I26: P | Q26: P | R26: P | S26: P | T26: P | AL26: =COUNTIF(G26:AK26,"P")+COUNTIF(G26:AK26,"PP")+COUNTIF(G26:AK26,"PP") -> 6 | AM26: 550 | AN26: =AL26*AM26 -> 3300
B27: Total Per Day | H27: =COUNTIF(H5:H26,"P")+COUNTIF(H5:H26,"PP")+COUNTIF(H5:H26,"PP") -> 1 | I27: =COUNTIF(I5:I26,"P")+COUNTIF(I5:I26,"PP")+COUNTIF(I5:I26,"PP") -> 1 | J27: =COUNTIF(J5:J26,"P")+COUNTIF(J5:J26,"PP")+COUNTIF(J5:J26,"PP") -> 2 | K27: =COUNTIF(K5:K26,"P")+COUNTIF(K5:K26,"PP")+COUNTIF(K5:K26,"PP") -> 2 | L27: =COUNTIF(L5:L26,"P")+COUNTIF(L5:L26,"PP")+COUNTIF(L5:L26,"PP") -> 2 | M27: =COUNTIF(M5:M26,"P")+COUNTIF(M5:M26,"PP")+COUNTIF(M5:M26,"PP") -> 7 | N27: =COUNTIF(N5:N26,"P")+COUNTIF(N5:N26,"PP")+COUNTIF(N5:N26,"PP") -> 5 | O27: =COUNTIF(O5:O26,"P")+COUNTIF(O5:O26,"PP")+COUNTIF(O5:O26,"PP") -> 6 | ... AK27: =COUNTIF(AK5:AK26,"P")+COUNTIF(AK5:AK26,"PP")+COUNTIF(AK5:AK26,"PP") -> 3 | AL27: =SUM(AL5:AL26) -> 146 | AN27: =SUM(AN5:AN26) -> 81300
B30: Masure Project Pvt. Ltd. | AM30: Rate | AN30: Monthly Salary
B31: OBHS Attendance sheet of 14650/49 (Rake-02) Month:- Jun-2026 Site Name:- Amritsar OBHS (Attendance Day Per trip:- 04)
B32: S.N. | C32: EMP CODE | D32: TA ID No. | E32: EMP Name | F32: Father's Name | G32: Dig | H32: 1 | I32: 2 | J32: 3 | K32: 4 | L32: 5 | M32: 6 | N32: 7 | O32: 8 | P32: 9 | Q32: 10 | R32: 11 | S32: 12 | T32: 13 | U32: 14 | V32: 15 | W32: 16 | X32: 17 | Y32: 18 | Z32: 19 | AA32: 20 | AB32: 21 | AC32: 22 | AD32: 23 | AE32: 24 | AF32: 25 | AG32: 26 | AH32: 27 | AI32: 28 | AJ32: 29 | AK32: 30 | AL32: Total
B33: 1 | C33: 33505 | D33: 102 | E33: SANDEEP SINGH | F33: SUKHBIR SINGH | G33: EHK | T33: P | U33: P | V33: P | W33: P | AL33: =COUNTIF(G33:AK33,"P")+COUNTIF(G33:AK33,"PP")+COUNTIF(G33:AK33,"PP") -> 4 | AM33: 600 | AN33: =AM33*AL33 -> 2400
B34: 2 | C34: 33581 | E34: PAVAN KUMAR SINGH | F34: BUBHASH CHANDRA SINGH | G34: EHK | O34: P | P34: P | Q34: P | R34: P | W34: P | X34: P | Y34: P | Z34: P | AA34: P | AB34: P | AC34: P | AD34: P | AE34: P | AF34: P | AG34: P | AH34: P | AL34: =COUNTIF(G34:AK34,"P")+COUNTIF(G34:AK34,"PP")+COUNTIF(G34:AK34,"PP") -> 16 | AM34: 600 | AN34: =AM34*AL34 -> 9600
B35: 3 | C35: 33504 | E35: RAHUL KUMAR | F35: AJAY KUMAR | G35: OBHS | M35: P | N35: P | O35: P | P35: P | AL35: =COUNTIF(G35:AK35,"P")+COUNTIF(G35:AK35,"PP")+COUNTIF(G35:AK35,"PP") -> 4 | AM35: 550 | AN35: =AM35*AL35 -> 2200
B36: 4 | C36: 33658 | E36: ARMAN | F36: JAHIR SINGH | G36: OBHS | J36: P | K36: P | L36: P | M36: P | V36: P | W36: P | X36: P | Y36: P | AL36: =COUNTIF(G36:AK36,"P")+COUNTIF(G36:AK36,"PP")+COUNTIF(G36:AK36,"PP") -> 8 | AM36: 550 | AN36: =AM36*AL36 -> 4400
B37: 5 | C37: 33858 | E37: RAVINDER SINGH | F37: BALKAR SINGH | G37: OBHS | J37: P | K37: P | L37: P | M37: P | AC37: P | AD37: P | AE37: P | AF37: P | AL37: =COUNTIF(G37:AK37,"P")+COUNTIF(G37:AK37,"PP")+COUNTIF(G37:AK37,"PP") -> 8 | AM37: 550 | AN37: =AM37*AL37 -> 4400
B38: 6 | C38: 33583 | E38: AJAY SINGH | F38: NARVEER SINGH | G38: OBHS | W38: P | X38: P | Y38: P | Z38: P | AA38: P | AB38: P | AC38: P | AD38: P | AE38: P | AF38: P | AG38: P | AH38: P | AL38: =COUNTIF(G38:AK38,"P")+COUNTIF(G38:AK38,"PP")+COUNTIF(G38:AK38,"PP") -> 12 | AM38: 550 | AN38: =AM38*AL38 -> 6600
B39: 7 | C39: 33861 | E39: ANURAG SHARMA | F39: VINOD KUMAR SHARMA | G39: OBHS | W39: P | X39: P | Y39: P | Z39: P | AA39: P | AB39: P | AC39: P | AD39: P | AE39: P | AF39: P | AG39: P | AH39: P | AL39: =COUNTIF(G39:AK39,"P")+COUNTIF(G39:AK39,"PP")+COUNTIF(G39:AK39,"PP") -> 12 | AM39: 550 | AN39: =AM39*AL39 -> 6600
B40: 8 | C40: 34482 | E40: SARBJIT SINGH | F40: BHAG SINGH | G40: OBHS | W40: P | X40: P | Y40: P | Z40: P | AL40: =COUNTIF(G40:AK40,"P")+COUNTIF(G40:AK40,"PP")+COUNTIF(G40:AK40,"PP") -> 4 | AM40: 550 | AN40: =AM40*AL40 -> 2200
B41: 9 | C41: 33533 | E41: RAJBIR SINGH | F41: TASVIR SINGH | G41: OBHS | H41: P | I41: P | AL41: =COUNTIF(G41:AK41,"P")+COUNTIF(G41:AK41,"PP")+COUNTIF(G41:AK41,"PP") -> 2 | AM41: 550 | AN41: =AM41*AL41 -> 1100
B42: 10 | C42: 33567 | E42: NARENDER | F42: CHANDER BHAN | G42: OBHS | H42: P | I42: P | J42: P | K42: P | L42: P | M42: P | T42: P | U42: P | V42: P | W42: P | X42: P | Y42: P | Z42: P | AA42: P | AL42: =COUNTIF(G42:AK42,"P")+COUNTIF(G42:AK42,"PP")+COUNTIF(G42:AK42,"PP") -> 14 | AM42: 550 | AN42: =AM42*AL42 -> 7700
B43: 11 | C43: 34155 | E43: TARSEM MASIH | F43: AMRIK SINGH | G43: OBHS | H43: P | I43: P | AL43: =COUNTIF(G43:AK43,"P")+COUNTIF(G43:AK43,"PP")+COUNTIF(G43:AK43,"PP") -> 2 | AM43: 550 | AN43: =AM43*AL43 -> 1100
...

Sheet 14674-73
B2: Masure Project Pvt. Ltd. | AM2: Rate/Day | AN2: Monthly Salary
B3: OBHS Attendance sheet of 14674/73 (Rake-01) Month:- Jun-2026 Site Name:- Amritsar OBHS (Attendance Day Per trip:- 04)
B4: S No. | C4: EMP CODE | D4: TA ID No. | E4: EMP Name | F4: Father's Name | G4: Dig | H4: 1 | I4: 2 | J4: 3 | K4: 4 | L4: 5 | M4: 6 | N4: 7 | O4: 8 | P4: 9 | Q4: 10 | R4: 11 | S4: 12 | T4: 13 | U4: 14 | V4: 15 | W4: 16 | X4: 17 | Y4: 18 | Z4: 19 | AA4: 20 | AB4: 21 | AC4: 22 | AD4: 23 | AE4: 24 | AF4: 25 | AG4: 26 | AH4: 27 | AI4: 28 | AJ4: 29 | AK4: 30 | AL4: Total
B5: 1 | C5: 33982 | E5: SHIVA | F5: VIJENDRA SINGH | G5: EHK | H5: P | I5: P | J5: P | K5: P | L5: P | M5: P | N5: P | O5: P | P5: P | Q5: P | R5: P | S5: P | AB5: P | AC5: P | AD5: P | AE5: P | AL5: =COUNTIF(G5:AK5,"P")+COUNTIF(G5:AK5,"PP")+COUNTIF(G5:AK5,"PP") -> 16 | AM5: 600 | AN5: =AL5*AM5 -> 9600
B6: 2 | C6: 33547 | E6: SUKHWINDER SINGH | F6: PAL SINGH | G6: EHK | H6: P | I6: P | J6: P | K6: P | L6: P | AD6: P | AE6: P | AF6: P | AG6: P | AL6: =COUNTIF(G6:AK6,"P")+COUNTIF(G6:AK6,"PP")+COUNTIF(G6:AK6,"PP") -> 9 | AM6: 600 | AN6: =AL6*AM6 -> 5400
B7: 3 | C7: 34154 | E7: SUKHPREET SINGH | F7: CHARANJIT SINGH | G7: OBHS | I7: P | J7: P | K7: P | L7: P | AK7: P | AL7: =COUNTIF(G7:AK7,"P")+COUNTIF(G7:AK7,"PP")+COUNTIF(G7:AK7,"PP") -> 5 | AM7: 550 | AN7: =AL7*AM7 -> 2750
B8: 4 | C8: 33849 | E8: AJAY KUMAR | F8: RAM VILAS | G8: OBHS | AG8: P | AH8: P | AI8: P | AJ8: P | AK8: P | AL8: =COUNTIF(G8:AK8,"P")+COUNTIF(G8:AK8,"PP")+COUNTIF(G8:AK8,"PP") -> 5 | AM8: 550 | AN8: =AL8*AM8 -> 2750
B9: 5 | C9: 33515 | E9: GURMAIL SINGH | F9: HARJINDER SINGH | G9: OBHS | H9: P | I9: P | J9: P | K9: P | L9: P | M9: P | N9: P | O9: P | P9: P | Q9: P | R9: P | S9: P | AB9: P | AC9: P | AD9: P | AE9: P | AF9: P | AG9: P | AH9: P | AI9: P | AJ9: P | AK9: P | AL9: =COUNTIF(G9:AK9,"P")+COUNTIF(G9:AK9,"PP")+COUNTIF(G9:AK9,"PP") -> 22 | AM9: 550 | AN9: =AL9*AM9 -> 12100
B10: 6 | C10: 34093 | E10: DEVENDRA AGRWAL | F10: VIRENDRA AGRAWAL | G10: OBHS | H10: P | I10: P | J10: P | K10: P | L10: P | M10: P | N10: P | O10: P | P10: P | Q10: P | R10: P | S10: P | AB10: P | AC10: P | AD10: P | AE10: P | AL10: =COUNTIF(G10:AK10,"P")+COUNTIF(G10:AK10,"PP")+COUNTIF(G10:AK10,"PP") -> 16 | AM10: 550 | AN10: =AL10*AM10 -> 8800
B11: 7 | C11: 33714 | E11: FARMAN | F11: RASSHAN KHAN | G11: OBHS | H11: P | I11: P | J11: P | K11: P | L11: P | M11: P | N11: P | O11: P | AL11: =COUNTIF(G11:AK11,"P")+COUNTIF(G11:AK11,"PP")+COUNTIF(G11:AK11,"PP") -> 8 | AM11: 550 | AN11: =AL11*AM11 -> 4400
B12: 8 | C12: 33718 | E12: ABHISHEK KUMAR | F12: HARIBABU | G12: OBHS | H12: P | I12: P | J12: P | K12: P | AL12: =COUNTIF(G12:AK12,"P")+COUNTIF(G12:AK12,"PP")+COUNTIF(G12:AK12,"PP") -> 4 | AM12: 550 | AN12: =AL12*AM12 -> 2200
B13: 9 | C13: 33712 | E13: MOHAMMAD AMAN | F13: IKLAKH AHAMAD | G13: OBHS | L13: P | M13: P | N13: P | O13: P | AL13: =COUNTIF(G13:AK13,"P")+COUNTIF(G13:AK13,"PP")+COUNTIF(G13:AK13,"PP") -> 4 | AM13: 550 | AN13: =AL13*AM13 -> 2200
B14: 10 | C14: 33637 | E14: ARJUN | F14: PURAN | G14: OBHS | H14: P | N14: P | O14: P | P14: P | Q14: P | R14: P | S14: P | T14: P | U14: P | Z14: P | AA14: P | AB14: P | AC14: P | AD14: P | AE14: P | AF14: P | AG14: P | AL14: =COUNTIF(G14:AK14,"P")+COUNTIF(G14:AK14,"PP")+COUNTIF(G14:AK14,"PP") -> 17 | AM14: 550 | AN14: =AL14*AM14 -> 9350
B15: 11 | C15: 34184 | E15: RAHUL KUMAR | F15: DEEPAK KUMAR | G15: OBHS | H15: P | I15: P | J15: P | K15: P | L15: P | N15: P | O15: P | P15: P | Q15: P | R15: P | S15: P | T15: P | U15: P | Z15: P | AA15: P | AB15: P | AC15: P | AD15: P | AE15: P | AF15: P | AG15: P | AL15: =COUNTIF(G15:AK15,"P")+COUNTIF(G15:AK15,"PP")+COUNTIF(G15:AK15,"PP") -> 21 | AM15: 550 | AN15: =AL15*AM15 -> 11550
B16: 12 | C16: 33883 | E16: LOVEPREET SINGH | F16: GULJAR SINGH | G16: OBHS | H16: P | AL16: =COUNTIF(G16:AK16,"P")+COUNTIF(G16:AK16,"PP")+COUNTIF(G16:AK16,"PP") -> 1 | AM16: 550 | AN16: =AL16*AM16 -> 550
B17: 13 | C17: 33581 | E17: PAVAN KUMAR SINGH | F17: BUBHASH CHANDRA | G17: EHK | H17: P | I17: P | J17: P | K17: P | L17: P | M17: P | N17: P | S17: P | T17: P | U17: P | V17: P | AI17: P | AJ17: P | AK17: P | AL17: =COUNTIF(G17:AK17,"P")+COUNTIF(G17:AK17,"PP")+COUNTIF(G17:AK17,"PP") -> 14 | AM17: 600 | AN17: =AL17*AM17 -> 8400
B18: 14 | C18: 34343 | E18: MANI SINGH | F18: JASPAL SINGH | G18: OBHS | H18: P | I18: P | J18: P | AL18: =COUNTIF(G18:AK18,"P")+COUNTIF(G18:AK18,"PP")+COUNTIF(G18:AK18,"PP") -> 3 | AM18: 550 | AN18: =AL18*AM18 -> 1650
B19: 15 | C19: 33585 | E19: ARSHDEEP SINGH | F19: CHARANJEET SINGH | G19: OBHS | AJ19: P | AK19: P | AL19: =COUNTIF(G19:AK19,"P")+COUNTIF(G19:AK19,"PP")+COUNTIF(G19:AK19,"PP") -> 2 | AM19: 550 | AN19: =AL19*AM19 -> 1100
B20: 16 | C20: 34280 | E20: AJAY SINGH | F20: DHEERA SINGH | G20: OBHS | K20: P | L20: P | M20: P | N20: P | S20: P | T20: P | U20: P | V20: P | AL20: =COUNTIF(G20:AK20,"P")+COUNTIF(G20:AK20,"PP")+COUNTIF(G20:AK20,"PP") -> 8 | AM20: 550 | AN20: =AL20*AM20 -> 4400
B21: 17 | C21: 34308 | E21: ANURAG SINGH | F21: JAIPAL SINGH | G21: OBHS | K21: P | L21: P | M21: P | N21: P | S21: P | T21: P | U21: P | V21: P | AL21: =COUNTIF(G21:AK21,"P")+COUNTIF(G21:AK21,"PP")+COUNTIF(G21:AK21,"PP") -> 8 | AM21: 550 | AN21: =AL21*AM21 -> 4400
B22: 18 | C22: 33752 | E22: GURPREET SINGH | F22: BEANT SINGH | G22: OBHS | P22: P | Q22: P | R22: P | S22: P | AL22: =COUNTIF(G22:AK22,"P")+COUNTIF(G22:AK22,"PP")+COUNTIF(G22:AK22,"PP") -> 4 | AM22: 550 | AN22: =AL22*AM22 -> 2200
B23: 19 | C23: 33509 | E23: NEETA | F23: SUDESH KUMAR | G23: OBHS | S23: P | T23: P | U23: P | V23: P | AL23: =COUNTIF(G23:AK23,"P")+COUNTIF(G23:AK23,"PP")+COUNTIF(G23:AK23,"PP") -> 4 | AM23: 550 | AN23: =AL23*AM23 -> 2200
B24: 20 | C24: 33517 | E24: SUKHWINDER SINGH | F24: JASWANT SINGH | G24: OBHS | U24: P | V24: P | W24: P | X24: P | Z24: P | AA24: P | AB24: P | AC24: P | AD24: P | AE24: P | AF24: P | AG24: P | AL24: =COUNTIF(G24:AK24,"P")+COUNTIF(G24:AK24,"PP")+COUNTIF(G24:AK24,"PP") -> 12 | AM24: 550 | AN24: =AL24*AM24 -> 6600
B25: 21 | C25: 33567 | E25: NARENDER | F25: CHANDER BHAN | G25: OBHS | N25: P | O25: P | P25: P | Q25: P | AF25: P | AG25: P | AH25: P | AI25: P | AJ25: P | AK25: P | AL25: =COUNTIF(G25:AK25,"P")+COUNTIF(G25:AK25,"PP")+COUNTIF(G25:AK25,"PP") -> 10 | AM25: 550 | AN25: =AL25*AM25 -> 5500
B26: 22 | C26: 33583 | E26: AJAY SINGH | F26: NARVEER SINGH | G26: OBHS | AI26: P | AJ26: P | AK26: P | AL26: =COUNTIF(G26:AK26,"P")+COUNTIF(G26:AK26,"PP")+COUNTIF(G26:AK26,"PP") -> 3 | AM26: 550 | AN26: =AL26*AM26 -> 1650
B27: 23 | C27: 33794 | E27: VISHAL SINGH | F27: RAKESH SINGH | G27: OBHS | AI27: P | AJ27: P | AK27: P | AL27: =COUNTIF(G27:AK27,"P")+COUNTIF(G27:AK27,"PP")+COUNTIF(G27:AK27,"PP") -> 3 | AM27: 550 | AN27: =AL27*AM27 -> 1650
B28: 24 | C28: 34048 | E28: SOURABH SEHGAL | F28: DES RAJ SEHGAL | G28: OBHS | AJ28: P | AK28: P | AL28: =COUNTIF(G28:AK28,"P")+COUNTIF(G28:AK28,"PP")+COUNTIF(G28:AK28,"PP") -> 2 | AM28: 550 | AN28: =AL28*AM28 -> 1100
B29: 25 | C29: 34002 | E29: CHANDAN SAGAR | F29: NET RAM | G29: OBHS | AK29: P | AL29: =COUNTIF(G29:AK29,"P")+COUNTIF(G29:AK29,"PP")+COUNTIF(G29:AK29,"PP") -> 1 | AM29: 550 | AN29: =AL29*AM29 -> 550
B30: 26 | C30: 34166 | E30: SIKANDER | F30: KALA RAM | G30: OBHS | AK30: P | AL30: =COUNTIF(G30:AK30,"P")+COUNTIF(G30:AK30,"PP")+COUNTIF(G30:AK30,"PP") -> 1 | AM30: 550 | AN30: =AL30*AM30 -> 550
B31: 27 | C31: 33711 | E31: SURAJ | F31: RANBIR SINGH | G31: OBHS | H31: P | I31: P | J31: P | AL31: =COUNTIF(G31:AK31,"P")+COUNTIF(G31:AK31,"PP")+COUNTIF(G31:AK31,"PP") -> 3 | AM31: 550 | AN31: =AL31*AM31 -> 1650
B32: Total Per Day | H32: =COUNTIF(H5:H31,"P")+COUNTIF(H5:H31,"PP")+COUNTIF(H5:H31,"PP") -> 12 | I32: =COUNTIF(I5:I31,"P")+COUNTIF(I5:I31,"PP")+COUNTIF(I5:I31,"PP") -> 11 | J32: =COUNTIF(J5:J31,"P")+COUNTIF(J5:J31,"PP")+COUNTIF(J5:J31,"PP") -> 11 | K32: =COUNTIF(K5:K31,"P")+COUNTIF(K5:K31,"PP")+COUNTIF(K5:K31,"PP") -> 11 | L32: =COUNTIF(L5:L31,"P")+COUNTIF(L5:L31,"PP")+COUNTIF(L5:L31,"PP") -> 11 | M32: =COUNTIF(M5:M31,"P")+COUNTIF(M5:M31,"PP")+COUNTIF(M5:M31,"PP") -> 8 | N32: =COUNTIF(N5:N31,"P")+COUNTIF(N5:N31,"PP")+COUNTIF(N5:N31,"PP") -> 11 | O32: =COUNTIF(O5:O31,"P")+COUNTIF(O5:O31,"PP")+COUNTIF(O5:O31,"PP") -> 8 | ... AK32: =COUNTIF(AK5:AK31,"P")+COUNTIF(AK5:AK31,"PP")+COUNTIF(AK5:AK31,"PP") -> 11 | AL32: =SUM(AL5:AL31) -> 206 | AN32: =SUM(AN5:AN31) -> 115250
B35: Masure Project Pvt. Ltd. | AM35: Rate/Day | AN35: Monthly Salary
B36: OBHS Attendance sheet of 14674-73 (Rake-02) Month:- Jun-2026 Site Name:- Amritsar OBHS (Attendance Day Per trip:- 04)
B37: S.N. | C37: EMP CODE | D37: TA ID No. | E37: EMP Name | F37: Father's Name | G37: Dig | H37: 1 | I37: 2 | J37: 3 | K37: 4 | L37: 5 | M37: 6 | N37: 7 | O37: 8 | P37: 9 | Q37: 10 | R37: 11 | S37: 12 | T37: 13 | U37: 14 | V37: 15 | W37: 16 | X37: 17 | Y37: 18 | Z37: 19 | AA37: 20 | AB37: 21 | AC37: 22 | AD37: 23 | AE37: 24 | AF37: 25 | AG37: 26 | AH37: 27 | AI37: 28 | AJ37: 29 | AK37: 30 | AL37: Total
B38: 1 | C38: 33505 | E38: SANDEEP SINGH | F38: SUKHBIR SINGH | G38: EHK | AJ38: P | AK38: P | AL38: =COUNTIF(G38:AK38,"P")+COUNTIF(G38:AK38,"PP")+COUNTIF(G38:AK38,"PP") -> 2 | AM38: 600 | AN38: =AL38*AM38 -> 1200
B39: 2 | C39: 33792 | D39: 86 | E39: ANOOP KUMAR | F39: KISHAN CHAND | G39: EHK | H39: P | I39: P | J39: P | K39: P | N39: P | O39: P | P39: P | Q39: P | AG39: P | AH39: P | AI39: P | AJ39: P | AK39: P | AL39: =COUNTIF(G39:AK39,"P")+COUNTIF(G39:AK39,"PP")+COUNTIF(G39:AK39,"PP") -> 13 | AM39: 600 | AN39: =AL39*AM39 -> 7800
